[2024-10-28T20:26:23.699+0000] {local_task_job_runner.py:123} INFO - ::group::Pre task execution logs
[2024-10-28T20:26:23.713+0000] {taskinstance.py:2612} INFO - Dependencies all met for dep_context=non-requeueable deps ti=<TaskInstance: tab_social_media.user_info manual__2024-10-28T18:17:02.510729+00:00 [queued]>
[2024-10-28T20:26:23.718+0000] {taskinstance.py:2612} INFO - Dependencies all met for dep_context=requeueable deps ti=<TaskInstance: tab_social_media.user_info manual__2024-10-28T18:17:02.510729+00:00 [queued]>
[2024-10-28T20:26:23.718+0000] {taskinstance.py:2865} INFO - Starting attempt 3 of 4
[2024-10-28T20:26:23.727+0000] {taskinstance.py:2888} INFO - Executing <Task(PythonOperator): user_info> on 2024-10-28 18:17:02.510729+00:00
[2024-10-28T20:26:23.737+0000] {warnings.py:112} WARNING - /home/***/.local/lib/python3.12/site-packages/***/task/task_runner/standard_task_runner.py:70: DeprecationWarning: This process (pid=2905) is multi-threaded, use of fork() may lead to deadlocks in the child.
  pid = os.fork()

[2024-10-28T20:26:23.738+0000] {standard_task_runner.py:72} INFO - Started process 2918 to run task
[2024-10-28T20:26:23.738+0000] {standard_task_runner.py:104} INFO - Running: ['***', 'tasks', 'run', 'tab_social_media', 'user_info', 'manual__2024-10-28T18:17:02.510729+00:00', '--job-id', '38', '--raw', '--subdir', 'DAGS_FOLDER/tab_social_media.py', '--cfg-path', '/tmp/tmpx9uxlgrg']
[2024-10-28T20:26:23.740+0000] {standard_task_runner.py:105} INFO - Job 38: Subtask user_info
[2024-10-28T20:26:23.773+0000] {task_command.py:467} INFO - Running <TaskInstance: tab_social_media.user_info manual__2024-10-28T18:17:02.510729+00:00 [running]> on host 7f9c284dabe4
[2024-10-28T20:26:23.838+0000] {taskinstance.py:3131} INFO - Exporting env vars: AIRFLOW_CTX_DAG_OWNER='daniel.cristancho' AIRFLOW_CTX_DAG_ID='tab_social_media' AIRFLOW_CTX_TASK_ID='user_info' AIRFLOW_CTX_EXECUTION_DATE='2024-10-28T18:17:02.510729+00:00' AIRFLOW_CTX_TRY_NUMBER='3' AIRFLOW_CTX_DAG_RUN_ID='manual__2024-10-28T18:17:02.510729+00:00'
[2024-10-28T20:26:23.839+0000] {taskinstance.py:731} INFO - ::endgroup::
[2024-10-28T20:26:25.649+0000] {user_info.py:36} INFO - Start extract loaded data
[2024-10-28T20:26:25.650+0000] {user_info.py:199} INFO - Staring data extraction for users data
[2024-10-28T20:26:25.981+0000] {user_info.py:203} INFO - 3 rows extracted from users data
[2024-10-28T20:26:25.981+0000] {user_info.py:204} INFO - Data extraction successfully finished
[2024-10-28T20:26:33.010+0000] {logging_mixin.py:190} INFO -             id       username  ... profile_picture_crr _merge
0  62668118123  next2level.co  ...                None   both
1   2369736506    lerigames66  ...                None   both
2   2040926788     daniersdan  ...                None   both

[3 rows x 16 columns]
[2024-10-28T20:26:33.012+0000] {user_info.py:53} INFO - Start update old data
[2024-10-28T20:26:34.387+0000] {logging_mixin.py:190} INFO - Exception while executing the postgresql query syntax error at or near "FROM"
LINE 16:     FROM cte AS t
             ^
[2024-10-28T20:26:34.387+0000] {logging_mixin.py:190} INFO - ****************** Unexpected error: syntax error at or near "FROM"
LINE 16:     FROM cte AS t
             ^
[2024-10-28T20:26:34.387+0000] {logging_mixin.py:190} INFO -  (<class 'psycopg2.errors.SyntaxError'>, SyntaxError('syntax error at or near "FROM"\nLINE 16:     FROM cte AS t\n             ^\n'), <traceback object at 0x75e4b1d58680>)
[2024-10-28T20:26:34.388+0000] {taskinstance.py:3310} ERROR - Task failed with exception
Traceback (most recent call last):
  File "/home/airflow/.local/lib/python3.12/site-packages/airflow/models/taskinstance.py", line 767, in _execute_task
    result = _execute_callable(context=context, **execute_callable_kwargs)
             ^^^^^^^^^^^^^^^^^^^^^^^^^^^^^^^^^^^^^^^^^^^^^^^^^^^^^^^^^^^^^
  File "/home/airflow/.local/lib/python3.12/site-packages/airflow/models/taskinstance.py", line 733, in _execute_callable
    return ExecutionCallableRunner(
           ^^^^^^^^^^^^^^^^^^^^^^^^
  File "/home/airflow/.local/lib/python3.12/site-packages/airflow/utils/operator_helpers.py", line 252, in run
    return self.func(*args, **kwargs)
           ^^^^^^^^^^^^^^^^^^^^^^^^^^
  File "/home/airflow/.local/lib/python3.12/site-packages/airflow/models/baseoperator.py", line 406, in wrapper
    return func(self, *args, **kwargs)
           ^^^^^^^^^^^^^^^^^^^^^^^^^^^
  File "/home/airflow/.local/lib/python3.12/site-packages/airflow/operators/python.py", line 238, in execute
    return_value = self.execute_callable()
                   ^^^^^^^^^^^^^^^^^^^^^^^
  File "/home/airflow/.local/lib/python3.12/site-packages/airflow/operators/python.py", line 256, in execute_callable
    return runner.run(*self.op_args, **self.op_kwargs)
           ^^^^^^^^^^^^^^^^^^^^^^^^^^^^^^^^^^^^^^^^^^^
  File "/home/airflow/.local/lib/python3.12/site-packages/airflow/utils/operator_helpers.py", line 252, in run
    return self.func(*args, **kwargs)
           ^^^^^^^^^^^^^^^^^^^^^^^^^^
  File "/opt/airflow/dags/tab_social_media.py", line 17, in user_info
    pf.run()
  File "/opt/airflow/dags/src/social_media/user_info.py", line 59, in run
    utils.postgresql_execute_query(
  File "/opt/airflow/dags/src/social_media/utils.py", line 52, in postgresql_execute_query
    cursor.execute(query_execute)
psycopg2.errors.SyntaxError: syntax error at or near "FROM"
LINE 16:     FROM cte AS t
             ^

[2024-10-28T20:26:34.399+0000] {taskinstance.py:1225} INFO - Marking task as UP_FOR_RETRY. dag_id=tab_social_media, task_id=user_info, run_id=manual__2024-10-28T18:17:02.510729+00:00, execution_date=20241028T181702, start_date=20241028T202623, end_date=20241028T202634
[2024-10-28T20:26:34.410+0000] {taskinstance.py:340} INFO - ::group::Post task execution logs
[2024-10-28T20:26:34.410+0000] {standard_task_runner.py:124} ERROR - Failed to execute job 38 for task user_info (syntax error at or near "FROM"
LINE 16:     FROM cte AS t
             ^
; 2918)
Traceback (most recent call last):
  File "/home/airflow/.local/lib/python3.12/site-packages/airflow/task/task_runner/standard_task_runner.py", line 117, in _start_by_fork
    ret = args.func(args, dag=self.dag)
          ^^^^^^^^^^^^^^^^^^^^^^^^^^^^^
  File "/home/airflow/.local/lib/python3.12/site-packages/airflow/cli/cli_config.py", line 49, in command
    return func(*args, **kwargs)
           ^^^^^^^^^^^^^^^^^^^^^
  File "/home/airflow/.local/lib/python3.12/site-packages/airflow/utils/cli.py", line 115, in wrapper
    return f(*args, **kwargs)
           ^^^^^^^^^^^^^^^^^^
  File "/home/airflow/.local/lib/python3.12/site-packages/airflow/cli/commands/task_command.py", line 483, in task_run
    task_return_code = _run_task_by_selected_method(args, _dag, ti)
                       ^^^^^^^^^^^^^^^^^^^^^^^^^^^^^^^^^^^^^^^^^^^^
  File "/home/airflow/.local/lib/python3.12/site-packages/airflow/cli/commands/task_command.py", line 256, in _run_task_by_selected_method
    return _run_raw_task(args, ti)
           ^^^^^^^^^^^^^^^^^^^^^^^
  File "/home/airflow/.local/lib/python3.12/site-packages/airflow/cli/commands/task_command.py", line 341, in _run_raw_task
    return ti._run_raw_task(
           ^^^^^^^^^^^^^^^^^
  File "/home/airflow/.local/lib/python3.12/site-packages/airflow/utils/session.py", line 97, in wrapper
    return func(*args, session=session, **kwargs)
           ^^^^^^^^^^^^^^^^^^^^^^^^^^^^^^^^^^^^^^
  File "/home/airflow/.local/lib/python3.12/site-packages/airflow/models/taskinstance.py", line 3004, in _run_raw_task
    return _run_raw_task(
           ^^^^^^^^^^^^^^
  File "/home/airflow/.local/lib/python3.12/site-packages/airflow/models/taskinstance.py", line 273, in _run_raw_task
    TaskInstance._execute_task_with_callbacks(
  File "/home/airflow/.local/lib/python3.12/site-packages/airflow/models/taskinstance.py", line 3158, in _execute_task_with_callbacks
    result = self._execute_task(context, task_orig)
             ^^^^^^^^^^^^^^^^^^^^^^^^^^^^^^^^^^^^^^
  File "/home/airflow/.local/lib/python3.12/site-packages/airflow/models/taskinstance.py", line 3182, in _execute_task
    return _execute_task(self, context, task_orig)
           ^^^^^^^^^^^^^^^^^^^^^^^^^^^^^^^^^^^^^^^
  File "/home/airflow/.local/lib/python3.12/site-packages/airflow/models/taskinstance.py", line 767, in _execute_task
    result = _execute_callable(context=context, **execute_callable_kwargs)
             ^^^^^^^^^^^^^^^^^^^^^^^^^^^^^^^^^^^^^^^^^^^^^^^^^^^^^^^^^^^^^
  File "/home/airflow/.local/lib/python3.12/site-packages/airflow/models/taskinstance.py", line 733, in _execute_callable
    return ExecutionCallableRunner(
           ^^^^^^^^^^^^^^^^^^^^^^^^
  File "/home/airflow/.local/lib/python3.12/site-packages/airflow/utils/operator_helpers.py", line 252, in run
    return self.func(*args, **kwargs)
           ^^^^^^^^^^^^^^^^^^^^^^^^^^
  File "/home/airflow/.local/lib/python3.12/site-packages/airflow/models/baseoperator.py", line 406, in wrapper
    return func(self, *args, **kwargs)
           ^^^^^^^^^^^^^^^^^^^^^^^^^^^
  File "/home/airflow/.local/lib/python3.12/site-packages/airflow/operators/python.py", line 238, in execute
    return_value = self.execute_callable()
                   ^^^^^^^^^^^^^^^^^^^^^^^
  File "/home/airflow/.local/lib/python3.12/site-packages/airflow/operators/python.py", line 256, in execute_callable
    return runner.run(*self.op_args, **self.op_kwargs)
           ^^^^^^^^^^^^^^^^^^^^^^^^^^^^^^^^^^^^^^^^^^^
  File "/home/airflow/.local/lib/python3.12/site-packages/airflow/utils/operator_helpers.py", line 252, in run
    return self.func(*args, **kwargs)
           ^^^^^^^^^^^^^^^^^^^^^^^^^^
  File "/opt/airflow/dags/tab_social_media.py", line 17, in user_info
    pf.run()
  File "/opt/airflow/dags/src/social_media/user_info.py", line 59, in run
    utils.postgresql_execute_query(
  File "/opt/airflow/dags/src/social_media/utils.py", line 52, in postgresql_execute_query
    cursor.execute(query_execute)
psycopg2.errors.SyntaxError: syntax error at or near "FROM"
LINE 16:     FROM cte AS t
             ^

[2024-10-28T20:26:34.447+0000] {local_task_job_runner.py:266} INFO - Task exited with return code 1
[2024-10-28T20:26:34.466+0000] {taskinstance.py:3900} INFO - 0 downstream tasks scheduled from follow-on schedule check
[2024-10-28T20:26:34.467+0000] {local_task_job_runner.py:245} INFO - ::endgroup::
