[2024-09-30T14:22:15.826+0000] {local_task_job_runner.py:123} INFO - ::group::Pre task execution logs
[2024-09-30T14:22:15.840+0000] {taskinstance.py:2612} INFO - Dependencies all met for dep_context=non-requeueable deps ti=<TaskInstance: tab_soccer_statics.fact_matches_statistics scheduled__2024-09-29T12:00:00+00:00 [queued]>
[2024-09-30T14:22:15.845+0000] {taskinstance.py:2612} INFO - Dependencies all met for dep_context=requeueable deps ti=<TaskInstance: tab_soccer_statics.fact_matches_statistics scheduled__2024-09-29T12:00:00+00:00 [queued]>
[2024-09-30T14:22:15.845+0000] {taskinstance.py:2865} INFO - Starting attempt 11 of 12
[2024-09-30T14:22:15.855+0000] {taskinstance.py:2888} INFO - Executing <Task(PythonOperator): fact_matches_statistics> on 2024-09-29 12:00:00+00:00
[2024-09-30T14:22:15.864+0000] {warnings.py:112} WARNING - /home/***/.local/lib/python3.12/site-packages/***/task/task_runner/standard_task_runner.py:70: DeprecationWarning: This process (pid=3656) is multi-threaded, use of fork() may lead to deadlocks in the child.
  pid = os.fork()

[2024-09-30T14:22:15.865+0000] {standard_task_runner.py:72} INFO - Started process 3669 to run task
[2024-09-30T14:22:15.866+0000] {standard_task_runner.py:104} INFO - Running: ['***', 'tasks', 'run', 'tab_soccer_statics', 'fact_matches_statistics', 'scheduled__2024-09-29T12:00:00+00:00', '--job-id', '167', '--raw', '--subdir', 'DAGS_FOLDER/tab_soccer_statics.py', '--cfg-path', '/tmp/tmph3drasgv']
[2024-09-30T14:22:15.867+0000] {standard_task_runner.py:105} INFO - Job 167: Subtask fact_matches_statistics
[2024-09-30T14:22:15.903+0000] {task_command.py:467} INFO - Running <TaskInstance: tab_soccer_statics.fact_matches_statistics scheduled__2024-09-29T12:00:00+00:00 [running]> on host 58fa97ed942d
[2024-09-30T14:22:15.970+0000] {taskinstance.py:3131} INFO - Exporting env vars: AIRFLOW_CTX_DAG_OWNER='daniel.cristancho' AIRFLOW_CTX_DAG_ID='tab_soccer_statics' AIRFLOW_CTX_TASK_ID='fact_matches_statistics' AIRFLOW_CTX_EXECUTION_DATE='2024-09-29T12:00:00+00:00' AIRFLOW_CTX_TRY_NUMBER='11' AIRFLOW_CTX_DAG_RUN_ID='scheduled__2024-09-29T12:00:00+00:00'
[2024-09-30T14:22:15.971+0000] {taskinstance.py:731} INFO - ::endgroup::
[2024-09-30T14:22:17.813+0000] {fact_matches_statics.py:32} INFO - Start extract loaded data
[2024-09-30T14:22:17.814+0000] {fact_matches_statics.py:187} INFO - Staring data extraction for dim_teams
[2024-09-30T14:22:19.184+0000] {fact_matches_statics.py:191} INFO - 80 rows extracted from dim_teams
[2024-09-30T14:22:19.184+0000] {fact_matches_statics.py:192} INFO - Data extraction successfully finished
[2024-09-30T14:22:19.184+0000] {fact_matches_statics.py:187} INFO - Staring data extraction for fact_matches_statistics
[2024-09-30T14:22:19.407+0000] {fact_matches_statics.py:191} INFO - 1 rows extracted from fact_matches_statistics
[2024-09-30T14:22:19.408+0000] {fact_matches_statics.py:192} INFO - Data extraction successfully finished
[2024-09-30T14:22:19.409+0000] {logging_mixin.py:190} INFO - ****************** Unexpected error update fact matches statistics:  (<class 'AttributeError'>, AttributeError("module 'pandas' has no attribute 'DataFram'"), <traceback object at 0x7299d7f15200>)
[2024-09-30T14:22:19.409+0000] {taskinstance.py:3310} ERROR - Task failed with exception
Traceback (most recent call last):
  File "/home/airflow/.local/lib/python3.12/site-packages/airflow/models/taskinstance.py", line 767, in _execute_task
    result = _execute_callable(context=context, **execute_callable_kwargs)
             ^^^^^^^^^^^^^^^^^^^^^^^^^^^^^^^^^^^^^^^^^^^^^^^^^^^^^^^^^^^^^
  File "/home/airflow/.local/lib/python3.12/site-packages/airflow/models/taskinstance.py", line 733, in _execute_callable
    return ExecutionCallableRunner(
           ^^^^^^^^^^^^^^^^^^^^^^^^
  File "/home/airflow/.local/lib/python3.12/site-packages/airflow/utils/operator_helpers.py", line 252, in run
    return self.func(*args, **kwargs)
           ^^^^^^^^^^^^^^^^^^^^^^^^^^
  File "/home/airflow/.local/lib/python3.12/site-packages/airflow/models/baseoperator.py", line 406, in wrapper
    return func(self, *args, **kwargs)
           ^^^^^^^^^^^^^^^^^^^^^^^^^^^
  File "/home/airflow/.local/lib/python3.12/site-packages/airflow/operators/python.py", line 238, in execute
    return_value = self.execute_callable()
                   ^^^^^^^^^^^^^^^^^^^^^^^
  File "/home/airflow/.local/lib/python3.12/site-packages/airflow/operators/python.py", line 256, in execute_callable
    return runner.run(*self.op_args, **self.op_kwargs)
           ^^^^^^^^^^^^^^^^^^^^^^^^^^^^^^^^^^^^^^^^^^^
  File "/home/airflow/.local/lib/python3.12/site-packages/airflow/utils/operator_helpers.py", line 252, in run
    return self.func(*args, **kwargs)
           ^^^^^^^^^^^^^^^^^^^^^^^^^^
  File "/opt/airflow/dags/tab_soccer_statics.py", line 83, in fact_matches_statistics
    pf.run()
  File "/opt/airflow/dags/src/soccer_statics/fact_matches_statics.py", line 44, in run
    results_list = pd.DataFram()
                   ^^^^^^^^^^^
AttributeError: module 'pandas' has no attribute 'DataFram'. Did you mean: 'DataFrame'?
[2024-09-30T14:22:19.420+0000] {taskinstance.py:1225} INFO - Marking task as UP_FOR_RETRY. dag_id=tab_soccer_statics, task_id=fact_matches_statistics, run_id=scheduled__2024-09-29T12:00:00+00:00, execution_date=20240929T120000, start_date=20240930T142215, end_date=20240930T142219
[2024-09-30T14:22:19.438+0000] {taskinstance.py:340} INFO - ::group::Post task execution logs
[2024-09-30T14:22:19.439+0000] {standard_task_runner.py:124} ERROR - Failed to execute job 167 for task fact_matches_statistics (module 'pandas' has no attribute 'DataFram'; 3669)
Traceback (most recent call last):
  File "/home/airflow/.local/lib/python3.12/site-packages/airflow/task/task_runner/standard_task_runner.py", line 117, in _start_by_fork
    ret = args.func(args, dag=self.dag)
          ^^^^^^^^^^^^^^^^^^^^^^^^^^^^^
  File "/home/airflow/.local/lib/python3.12/site-packages/airflow/cli/cli_config.py", line 49, in command
    return func(*args, **kwargs)
           ^^^^^^^^^^^^^^^^^^^^^
  File "/home/airflow/.local/lib/python3.12/site-packages/airflow/utils/cli.py", line 115, in wrapper
    return f(*args, **kwargs)
           ^^^^^^^^^^^^^^^^^^
  File "/home/airflow/.local/lib/python3.12/site-packages/airflow/cli/commands/task_command.py", line 483, in task_run
    task_return_code = _run_task_by_selected_method(args, _dag, ti)
                       ^^^^^^^^^^^^^^^^^^^^^^^^^^^^^^^^^^^^^^^^^^^^
  File "/home/airflow/.local/lib/python3.12/site-packages/airflow/cli/commands/task_command.py", line 256, in _run_task_by_selected_method
    return _run_raw_task(args, ti)
           ^^^^^^^^^^^^^^^^^^^^^^^
  File "/home/airflow/.local/lib/python3.12/site-packages/airflow/cli/commands/task_command.py", line 341, in _run_raw_task
    return ti._run_raw_task(
           ^^^^^^^^^^^^^^^^^
  File "/home/airflow/.local/lib/python3.12/site-packages/airflow/utils/session.py", line 97, in wrapper
    return func(*args, session=session, **kwargs)
           ^^^^^^^^^^^^^^^^^^^^^^^^^^^^^^^^^^^^^^
  File "/home/airflow/.local/lib/python3.12/site-packages/airflow/models/taskinstance.py", line 3004, in _run_raw_task
    return _run_raw_task(
           ^^^^^^^^^^^^^^
  File "/home/airflow/.local/lib/python3.12/site-packages/airflow/models/taskinstance.py", line 273, in _run_raw_task
    TaskInstance._execute_task_with_callbacks(
  File "/home/airflow/.local/lib/python3.12/site-packages/airflow/models/taskinstance.py", line 3158, in _execute_task_with_callbacks
    result = self._execute_task(context, task_orig)
             ^^^^^^^^^^^^^^^^^^^^^^^^^^^^^^^^^^^^^^
  File "/home/airflow/.local/lib/python3.12/site-packages/airflow/models/taskinstance.py", line 3182, in _execute_task
    return _execute_task(self, context, task_orig)
           ^^^^^^^^^^^^^^^^^^^^^^^^^^^^^^^^^^^^^^^
  File "/home/airflow/.local/lib/python3.12/site-packages/airflow/models/taskinstance.py", line 767, in _execute_task
    result = _execute_callable(context=context, **execute_callable_kwargs)
             ^^^^^^^^^^^^^^^^^^^^^^^^^^^^^^^^^^^^^^^^^^^^^^^^^^^^^^^^^^^^^
  File "/home/airflow/.local/lib/python3.12/site-packages/airflow/models/taskinstance.py", line 733, in _execute_callable
    return ExecutionCallableRunner(
           ^^^^^^^^^^^^^^^^^^^^^^^^
  File "/home/airflow/.local/lib/python3.12/site-packages/airflow/utils/operator_helpers.py", line 252, in run
    return self.func(*args, **kwargs)
           ^^^^^^^^^^^^^^^^^^^^^^^^^^
  File "/home/airflow/.local/lib/python3.12/site-packages/airflow/models/baseoperator.py", line 406, in wrapper
    return func(self, *args, **kwargs)
           ^^^^^^^^^^^^^^^^^^^^^^^^^^^
  File "/home/airflow/.local/lib/python3.12/site-packages/airflow/operators/python.py", line 238, in execute
    return_value = self.execute_callable()
                   ^^^^^^^^^^^^^^^^^^^^^^^
  File "/home/airflow/.local/lib/python3.12/site-packages/airflow/operators/python.py", line 256, in execute_callable
    return runner.run(*self.op_args, **self.op_kwargs)
           ^^^^^^^^^^^^^^^^^^^^^^^^^^^^^^^^^^^^^^^^^^^
  File "/home/airflow/.local/lib/python3.12/site-packages/airflow/utils/operator_helpers.py", line 252, in run
    return self.func(*args, **kwargs)
           ^^^^^^^^^^^^^^^^^^^^^^^^^^
  File "/opt/airflow/dags/tab_soccer_statics.py", line 83, in fact_matches_statistics
    pf.run()
  File "/opt/airflow/dags/src/soccer_statics/fact_matches_statics.py", line 44, in run
    results_list = pd.DataFram()
                   ^^^^^^^^^^^
AttributeError: module 'pandas' has no attribute 'DataFram'. Did you mean: 'DataFrame'?
[2024-09-30T14:22:19.489+0000] {local_task_job_runner.py:266} INFO - Task exited with return code 1
[2024-09-30T14:22:19.503+0000] {taskinstance.py:3900} INFO - 0 downstream tasks scheduled from follow-on schedule check
[2024-09-30T14:22:19.504+0000] {local_task_job_runner.py:245} INFO - ::endgroup::
