[2024-10-28T21:15:43.945+0000] {local_task_job_runner.py:123} INFO - ::group::Pre task execution logs
[2024-10-28T21:15:44.242+0000] {taskinstance.py:2612} INFO - Dependencies all met for dep_context=non-requeueable deps ti=<TaskInstance: tab_refresh_stats.daily_instagram_stats manual__2024-10-28T21:15:42.467645+00:00 [queued]>
[2024-10-28T21:15:44.252+0000] {taskinstance.py:2612} INFO - Dependencies all met for dep_context=requeueable deps ti=<TaskInstance: tab_refresh_stats.daily_instagram_stats manual__2024-10-28T21:15:42.467645+00:00 [queued]>
[2024-10-28T21:15:44.252+0000] {taskinstance.py:2865} INFO - Starting attempt 1 of 2
[2024-10-28T21:15:44.268+0000] {taskinstance.py:2888} INFO - Executing <Task(PythonOperator): daily_instagram_stats> on 2024-10-28 21:15:42.467645+00:00
[2024-10-28T21:15:44.281+0000] {warnings.py:112} WARNING - /home/***/.local/lib/python3.12/site-packages/***/task/task_runner/standard_task_runner.py:70: DeprecationWarning: This process (pid=589) is multi-threaded, use of fork() may lead to deadlocks in the child.
  pid = os.fork()

[2024-10-28T21:15:44.283+0000] {standard_task_runner.py:72} INFO - Started process 593 to run task
[2024-10-28T21:15:44.283+0000] {standard_task_runner.py:104} INFO - Running: ['***', 'tasks', 'run', 'tab_refresh_stats', 'daily_instagram_stats', 'manual__2024-10-28T21:15:42.467645+00:00', '--job-id', '14', '--raw', '--subdir', 'DAGS_FOLDER/tab_social_media_refresh.py', '--cfg-path', '/tmp/tmpka2i7dg0']
[2024-10-28T21:15:44.286+0000] {standard_task_runner.py:105} INFO - Job 14: Subtask daily_instagram_stats
[2024-10-28T21:15:44.346+0000] {task_command.py:467} INFO - Running <TaskInstance: tab_refresh_stats.daily_instagram_stats manual__2024-10-28T21:15:42.467645+00:00 [running]> on host 721aaaeb5415
[2024-10-28T21:15:44.495+0000] {taskinstance.py:3131} INFO - Exporting env vars: AIRFLOW_CTX_DAG_OWNER='daniel.cristancho' AIRFLOW_CTX_DAG_ID='tab_refresh_stats' AIRFLOW_CTX_TASK_ID='daily_instagram_stats' AIRFLOW_CTX_EXECUTION_DATE='2024-10-28T21:15:42.467645+00:00' AIRFLOW_CTX_TRY_NUMBER='1' AIRFLOW_CTX_DAG_RUN_ID='manual__2024-10-28T21:15:42.467645+00:00'
[2024-10-28T21:15:44.497+0000] {taskinstance.py:731} INFO - ::endgroup::
[2024-10-28T21:15:46.265+0000] {evolution_stats_instagram.py:35} INFO - Start extract loaded data
[2024-10-28T21:15:51.989+0000] {evolution_stats_instagram.py:38} INFO - Start load new data
[2024-10-28T21:15:51.990+0000] {evolution_stats_instagram.py:108} INFO - writing user_follow_stats table
[2024-10-28T21:15:54.309+0000] {logging_mixin.py:190} WARNING - --- Logging error ---
[2024-10-28T21:15:54.310+0000] {logging_mixin.py:190} WARNING - Traceback (most recent call last):
[2024-10-28T21:15:54.311+0000] {logging_mixin.py:190} WARNING -   File "/opt/***/dags/src/social_media/evolution_stats_instagram.py", line 109, in __load
    conn.execute_insert(
[2024-10-28T21:15:54.311+0000] {logging_mixin.py:190} WARNING -   File "/opt/***/dags/next_connection/data_connection.py", line 200, in execute_insert
    cursor.copy_expert(copy_cmd, string_data_io)
[2024-10-28T21:15:54.311+0000] {logging_mixin.py:190} WARNING - psycopg2.errors.UniqueViolation: duplicate key value violates unique constraint "user_follow_stats_user_id_date_key"
DETAIL:  Key (user_id, date)=(232192182, 2024-10-28 21:15:51) already exists.
CONTEXT:  COPY user_follow_stats, line 2
[2024-10-28T21:15:54.312+0000] {logging_mixin.py:190} WARNING - 
During handling of the above exception, another exception occurred:
[2024-10-28T21:15:54.312+0000] {logging_mixin.py:190} WARNING - Traceback (most recent call last):
[2024-10-28T21:15:54.312+0000] {logging_mixin.py:190} WARNING -   File "/usr/local/lib/python3.12/logging/__init__.py", line 1160, in emit
    msg = self.format(record)
          ^^^^^^^^^^^^^^^^^^^
[2024-10-28T21:15:54.312+0000] {logging_mixin.py:190} WARNING -   File "/usr/local/lib/python3.12/logging/__init__.py", line 999, in format
    return fmt.format(record)
           ^^^^^^^^^^^^^^^^^^
[2024-10-28T21:15:54.313+0000] {logging_mixin.py:190} WARNING -   File "/usr/local/lib/python3.12/logging/__init__.py", line 703, in format
    record.message = record.getMessage()
                     ^^^^^^^^^^^^^^^^^^^
[2024-10-28T21:15:54.313+0000] {logging_mixin.py:190} WARNING -   File "/usr/local/lib/python3.12/logging/__init__.py", line 392, in getMessage
    msg = msg % self.args
          ~~~~^~~~~~~~~~~
[2024-10-28T21:15:54.313+0000] {logging_mixin.py:190} WARNING - TypeError: not all arguments converted during string formatting
[2024-10-28T21:15:54.313+0000] {logging_mixin.py:190} WARNING - Call stack:
[2024-10-28T21:15:54.332+0000] {logging_mixin.py:190} WARNING -   File "/home/***/.local/bin/***", line 8, in <module>
    sys.exit(main())
[2024-10-28T21:15:54.332+0000] {logging_mixin.py:190} WARNING -   File "/home/***/.local/lib/python3.12/site-packages/***/__main__.py", line 62, in main
    args.func(args)
[2024-10-28T21:15:54.332+0000] {logging_mixin.py:190} WARNING -   File "/home/***/.local/lib/python3.12/site-packages/***/cli/cli_config.py", line 49, in command
    return func(*args, **kwargs)
[2024-10-28T21:15:54.333+0000] {logging_mixin.py:190} WARNING -   File "/home/***/.local/lib/python3.12/site-packages/***/utils/cli.py", line 115, in wrapper
    return f(*args, **kwargs)
[2024-10-28T21:15:54.333+0000] {logging_mixin.py:190} WARNING -   File "/home/***/.local/lib/python3.12/site-packages/***/providers/celery/cli/celery_command.py", line 61, in wrapper
    providers_configuration_loaded(func)(*args, **kwargs)
[2024-10-28T21:15:54.333+0000] {logging_mixin.py:190} WARNING -   File "/home/***/.local/lib/python3.12/site-packages/***/utils/providers_configuration_loader.py", line 55, in wrapped_function
    return func(*args, **kwargs)
[2024-10-28T21:15:54.333+0000] {logging_mixin.py:190} WARNING -   File "/home/***/.local/lib/python3.12/site-packages/***/providers/celery/cli/celery_command.py", line 234, in worker
    _run_command_with_daemon_option(
[2024-10-28T21:15:54.333+0000] {logging_mixin.py:190} WARNING -   File "/home/***/.local/lib/python3.12/site-packages/***/providers/celery/cli/celery_command.py", line 47, in _run_command_with_daemon_option
    run_command_with_daemon_option(*args, **kwargs)
[2024-10-28T21:15:54.334+0000] {logging_mixin.py:190} WARNING -   File "/home/***/.local/lib/python3.12/site-packages/***/cli/commands/daemon_utils.py", line 86, in run_command_with_daemon_option
    callback()
[2024-10-28T21:15:54.334+0000] {logging_mixin.py:190} WARNING -   File "/home/***/.local/lib/python3.12/site-packages/***/providers/celery/cli/celery_command.py", line 227, in run_celery_worker
    celery_app.worker_main(options)
[2024-10-28T21:15:54.334+0000] {logging_mixin.py:190} WARNING -   File "/home/***/.local/lib/python3.12/site-packages/celery/app/base.py", line 391, in worker_main
    self.start(argv=argv)
[2024-10-28T21:15:54.334+0000] {logging_mixin.py:190} WARNING -   File "/home/***/.local/lib/python3.12/site-packages/celery/app/base.py", line 371, in start
    celery.main(args=argv, standalone_mode=False)
[2024-10-28T21:15:54.334+0000] {logging_mixin.py:190} WARNING -   File "/home/***/.local/lib/python3.12/site-packages/click/core.py", line 1078, in main
    rv = self.invoke(ctx)
[2024-10-28T21:15:54.335+0000] {logging_mixin.py:190} WARNING -   File "/home/***/.local/lib/python3.12/site-packages/click/core.py", line 1688, in invoke
    return _process_result(sub_ctx.command.invoke(sub_ctx))
[2024-10-28T21:15:54.335+0000] {logging_mixin.py:190} WARNING -   File "/home/***/.local/lib/python3.12/site-packages/click/core.py", line 1434, in invoke
    return ctx.invoke(self.callback, **ctx.params)
[2024-10-28T21:15:54.335+0000] {logging_mixin.py:190} WARNING -   File "/home/***/.local/lib/python3.12/site-packages/click/core.py", line 783, in invoke
    return __callback(*args, **kwargs)
[2024-10-28T21:15:54.335+0000] {logging_mixin.py:190} WARNING -   File "/home/***/.local/lib/python3.12/site-packages/click/decorators.py", line 33, in new_func
    return f(get_current_context(), *args, **kwargs)
[2024-10-28T21:15:54.335+0000] {logging_mixin.py:190} WARNING -   File "/home/***/.local/lib/python3.12/site-packages/celery/bin/base.py", line 135, in caller
    return f(ctx, *args, **kwargs)
[2024-10-28T21:15:54.336+0000] {logging_mixin.py:190} WARNING -   File "/home/***/.local/lib/python3.12/site-packages/celery/bin/worker.py", line 356, in worker
    worker.start()
[2024-10-28T21:15:54.336+0000] {logging_mixin.py:190} WARNING -   File "/home/***/.local/lib/python3.12/site-packages/celery/worker/worker.py", line 202, in start
    self.blueprint.start(self)
[2024-10-28T21:15:54.336+0000] {logging_mixin.py:190} WARNING -   File "/home/***/.local/lib/python3.12/site-packages/celery/bootsteps.py", line 116, in start
    step.start(parent)
[2024-10-28T21:15:54.336+0000] {logging_mixin.py:190} WARNING -   File "/home/***/.local/lib/python3.12/site-packages/celery/bootsteps.py", line 365, in start
    return self.obj.start()
[2024-10-28T21:15:54.336+0000] {logging_mixin.py:190} WARNING -   File "/home/***/.local/lib/python3.12/site-packages/celery/concurrency/base.py", line 130, in start
    self.on_start()
[2024-10-28T21:15:54.337+0000] {logging_mixin.py:190} WARNING -   File "/home/***/.local/lib/python3.12/site-packages/celery/concurrency/prefork.py", line 109, in on_start
    P = self._pool = Pool(processes=self.limit,
[2024-10-28T21:15:54.337+0000] {logging_mixin.py:190} WARNING -   File "/home/***/.local/lib/python3.12/site-packages/celery/concurrency/asynpool.py", line 464, in __init__
    super().__init__(processes, *args, **kwargs)
[2024-10-28T21:15:54.337+0000] {logging_mixin.py:190} WARNING -   File "/home/***/.local/lib/python3.12/site-packages/billiard/pool.py", line 1045, in __init__
    self._create_worker_process(i)
[2024-10-28T21:15:54.337+0000] {logging_mixin.py:190} WARNING -   File "/home/***/.local/lib/python3.12/site-packages/celery/concurrency/asynpool.py", line 482, in _create_worker_process
    return super()._create_worker_process(i)
[2024-10-28T21:15:54.337+0000] {logging_mixin.py:190} WARNING -   File "/home/***/.local/lib/python3.12/site-packages/billiard/pool.py", line 1157, in _create_worker_process
    w.start()
[2024-10-28T21:15:54.338+0000] {logging_mixin.py:190} WARNING -   File "/home/***/.local/lib/python3.12/site-packages/billiard/process.py", line 120, in start
    self._popen = self._Popen(self)
[2024-10-28T21:15:54.338+0000] {logging_mixin.py:190} WARNING -   File "/home/***/.local/lib/python3.12/site-packages/billiard/context.py", line 331, in _Popen
    return Popen(process_obj)
[2024-10-28T21:15:54.338+0000] {logging_mixin.py:190} WARNING -   File "/home/***/.local/lib/python3.12/site-packages/billiard/popen_fork.py", line 22, in __init__
    self._launch(process_obj)
[2024-10-28T21:15:54.338+0000] {logging_mixin.py:190} WARNING -   File "/home/***/.local/lib/python3.12/site-packages/billiard/popen_fork.py", line 77, in _launch
    code = process_obj._bootstrap()
[2024-10-28T21:15:54.338+0000] {logging_mixin.py:190} WARNING -   File "/home/***/.local/lib/python3.12/site-packages/billiard/process.py", line 323, in _bootstrap
    self.run()
[2024-10-28T21:15:54.339+0000] {logging_mixin.py:190} WARNING -   File "/home/***/.local/lib/python3.12/site-packages/billiard/process.py", line 110, in run
    self._target(*self._args, **self._kwargs)
[2024-10-28T21:15:54.339+0000] {logging_mixin.py:190} WARNING -   File "/home/***/.local/lib/python3.12/site-packages/billiard/pool.py", line 291, in __call__
    sys.exit(self.workloop(pid=pid))
[2024-10-28T21:15:54.339+0000] {logging_mixin.py:190} WARNING -   File "/home/***/.local/lib/python3.12/site-packages/billiard/pool.py", line 361, in workloop
    result = (True, prepare_result(fun(*args, **kwargs)))
[2024-10-28T21:15:54.339+0000] {logging_mixin.py:190} WARNING -   File "/home/***/.local/lib/python3.12/site-packages/celery/app/trace.py", line 651, in fast_trace_task
    R, I, T, Rstr = tasks[task].__trace__(
[2024-10-28T21:15:54.340+0000] {logging_mixin.py:190} WARNING -   File "/home/***/.local/lib/python3.12/site-packages/celery/app/trace.py", line 453, in trace_task
    R = retval = fun(*args, **kwargs)
[2024-10-28T21:15:54.340+0000] {logging_mixin.py:190} WARNING -   File "/home/***/.local/lib/python3.12/site-packages/celery/app/trace.py", line 736, in __protected_call__
    return self.run(*args, **kwargs)
[2024-10-28T21:15:54.340+0000] {logging_mixin.py:190} WARNING -   File "/home/***/.local/lib/python3.12/site-packages/***/providers/celery/executors/celery_executor_utils.py", line 135, in execute_command
    _execute_in_fork(command_to_exec, celery_task_id)
[2024-10-28T21:15:54.340+0000] {logging_mixin.py:190} WARNING -   File "/home/***/.local/lib/python3.12/site-packages/***/providers/celery/executors/celery_executor_utils.py", line 171, in _execute_in_fork
    args.func(args)
[2024-10-28T21:15:54.340+0000] {logging_mixin.py:190} WARNING -   File "/home/***/.local/lib/python3.12/site-packages/***/cli/cli_config.py", line 49, in command
    return func(*args, **kwargs)
[2024-10-28T21:15:54.341+0000] {logging_mixin.py:190} WARNING -   File "/home/***/.local/lib/python3.12/site-packages/***/utils/cli.py", line 115, in wrapper
    return f(*args, **kwargs)
[2024-10-28T21:15:54.341+0000] {logging_mixin.py:190} WARNING -   File "/home/***/.local/lib/python3.12/site-packages/***/cli/commands/task_command.py", line 483, in task_run
    task_return_code = _run_task_by_selected_method(args, _dag, ti)
[2024-10-28T21:15:54.341+0000] {logging_mixin.py:190} WARNING -   File "/home/***/.local/lib/python3.12/site-packages/***/cli/commands/task_command.py", line 254, in _run_task_by_selected_method
    return _run_task_by_local_task_job(args, ti)
[2024-10-28T21:15:54.341+0000] {logging_mixin.py:190} WARNING -   File "/home/***/.local/lib/python3.12/site-packages/***/cli/commands/task_command.py", line 322, in _run_task_by_local_task_job
    ret = run_job(job=job_runner.job, execute_callable=job_runner._execute)
[2024-10-28T21:15:54.342+0000] {logging_mixin.py:190} WARNING -   File "/home/***/.local/lib/python3.12/site-packages/***/utils/session.py", line 97, in wrapper
    return func(*args, session=session, **kwargs)
[2024-10-28T21:15:54.342+0000] {logging_mixin.py:190} WARNING -   File "/home/***/.local/lib/python3.12/site-packages/***/jobs/job.py", line 421, in run_job
    return execute_job(job, execute_callable=execute_callable)
[2024-10-28T21:15:54.342+0000] {logging_mixin.py:190} WARNING -   File "/home/***/.local/lib/python3.12/site-packages/***/jobs/job.py", line 450, in execute_job
    ret = execute_callable()
[2024-10-28T21:15:54.342+0000] {logging_mixin.py:190} WARNING -   File "/home/***/.local/lib/python3.12/site-packages/***/jobs/local_task_job_runner.py", line 171, in _execute
    self.task_runner.start()
[2024-10-28T21:15:54.343+0000] {logging_mixin.py:190} WARNING -   File "/home/***/.local/lib/python3.12/site-packages/***/task/task_runner/standard_task_runner.py", line 55, in start
    self.process = self._start_by_fork()
[2024-10-28T21:15:54.343+0000] {logging_mixin.py:190} WARNING -   File "/home/***/.local/lib/python3.12/site-packages/***/task/task_runner/standard_task_runner.py", line 117, in _start_by_fork
    ret = args.func(args, dag=self.dag)
[2024-10-28T21:15:54.343+0000] {logging_mixin.py:190} WARNING -   File "/home/***/.local/lib/python3.12/site-packages/***/cli/cli_config.py", line 49, in command
    return func(*args, **kwargs)
[2024-10-28T21:15:54.343+0000] {logging_mixin.py:190} WARNING -   File "/home/***/.local/lib/python3.12/site-packages/***/utils/cli.py", line 115, in wrapper
    return f(*args, **kwargs)
[2024-10-28T21:15:54.343+0000] {logging_mixin.py:190} WARNING -   File "/home/***/.local/lib/python3.12/site-packages/***/cli/commands/task_command.py", line 483, in task_run
    task_return_code = _run_task_by_selected_method(args, _dag, ti)
[2024-10-28T21:15:54.344+0000] {logging_mixin.py:190} WARNING -   File "/home/***/.local/lib/python3.12/site-packages/***/cli/commands/task_command.py", line 256, in _run_task_by_selected_method
    return _run_raw_task(args, ti)
[2024-10-28T21:15:54.344+0000] {logging_mixin.py:190} WARNING -   File "/home/***/.local/lib/python3.12/site-packages/***/cli/commands/task_command.py", line 341, in _run_raw_task
    return ti._run_raw_task(
[2024-10-28T21:15:54.344+0000] {logging_mixin.py:190} WARNING -   File "/home/***/.local/lib/python3.12/site-packages/***/utils/session.py", line 97, in wrapper
    return func(*args, session=session, **kwargs)
[2024-10-28T21:15:54.344+0000] {logging_mixin.py:190} WARNING -   File "/home/***/.local/lib/python3.12/site-packages/***/models/taskinstance.py", line 3004, in _run_raw_task
    return _run_raw_task(
[2024-10-28T21:15:54.345+0000] {logging_mixin.py:190} WARNING -   File "/home/***/.local/lib/python3.12/site-packages/***/models/taskinstance.py", line 273, in _run_raw_task
    TaskInstance._execute_task_with_callbacks(
[2024-10-28T21:15:54.345+0000] {logging_mixin.py:190} WARNING -   File "/home/***/.local/lib/python3.12/site-packages/***/models/taskinstance.py", line 3158, in _execute_task_with_callbacks
    result = self._execute_task(context, task_orig)
[2024-10-28T21:15:54.345+0000] {logging_mixin.py:190} WARNING -   File "/home/***/.local/lib/python3.12/site-packages/***/models/taskinstance.py", line 3182, in _execute_task
    return _execute_task(self, context, task_orig)
[2024-10-28T21:15:54.345+0000] {logging_mixin.py:190} WARNING -   File "/home/***/.local/lib/python3.12/site-packages/***/models/taskinstance.py", line 767, in _execute_task
    result = _execute_callable(context=context, **execute_callable_kwargs)
[2024-10-28T21:15:54.345+0000] {logging_mixin.py:190} WARNING -   File "/home/***/.local/lib/python3.12/site-packages/***/models/taskinstance.py", line 733, in _execute_callable
    return ExecutionCallableRunner(
[2024-10-28T21:15:54.346+0000] {logging_mixin.py:190} WARNING -   File "/home/***/.local/lib/python3.12/site-packages/***/utils/operator_helpers.py", line 252, in run
    return self.func(*args, **kwargs)
[2024-10-28T21:15:54.346+0000] {logging_mixin.py:190} WARNING -   File "/home/***/.local/lib/python3.12/site-packages/***/models/baseoperator.py", line 406, in wrapper
    return func(self, *args, **kwargs)
[2024-10-28T21:15:54.346+0000] {logging_mixin.py:190} WARNING -   File "/home/***/.local/lib/python3.12/site-packages/***/operators/python.py", line 238, in execute
    return_value = self.execute_callable()
[2024-10-28T21:15:54.346+0000] {logging_mixin.py:190} WARNING -   File "/home/***/.local/lib/python3.12/site-packages/***/operators/python.py", line 256, in execute_callable
    return runner.run(*self.op_args, **self.op_kwargs)
[2024-10-28T21:15:54.347+0000] {logging_mixin.py:190} WARNING -   File "/home/***/.local/lib/python3.12/site-packages/***/utils/operator_helpers.py", line 252, in run
    return self.func(*args, **kwargs)
[2024-10-28T21:15:54.347+0000] {logging_mixin.py:190} WARNING -   File "/opt/***/dags/tab_social_media_refresh.py", line 12, in daily_instagram_stats
    pf.run()
[2024-10-28T21:15:54.347+0000] {logging_mixin.py:190} WARNING -   File "/opt/***/dags/src/social_media/evolution_stats_instagram.py", line 39, in run
    self.__load(
[2024-10-28T21:15:54.347+0000] {logging_mixin.py:190} WARNING -   File "/opt/***/dags/src/social_media/evolution_stats_instagram.py", line 117, in __load
    self.__logger.error(
[2024-10-28T21:15:54.347+0000] {logging_mixin.py:190} WARNING -   File "/usr/local/lib/python3.12/logging/__init__.py", line 1568, in error
    self._log(ERROR, msg, args, **kwargs)
[2024-10-28T21:15:54.348+0000] {logging_mixin.py:190} WARNING -   File "/usr/local/lib/python3.12/logging/__init__.py", line 1684, in _log
    self.handle(record)
[2024-10-28T21:15:54.348+0000] {logging_mixin.py:190} WARNING -   File "/usr/local/lib/python3.12/logging/__init__.py", line 1700, in handle
    self.callHandlers(record)
[2024-10-28T21:15:54.348+0000] {logging_mixin.py:190} WARNING -   File "/usr/local/lib/python3.12/logging/__init__.py", line 1762, in callHandlers
    hdlr.handle(record)
[2024-10-28T21:15:54.348+0000] {logging_mixin.py:190} WARNING -   File "/usr/local/lib/python3.12/logging/__init__.py", line 1028, in handle
    self.emit(record)
[2024-10-28T21:15:54.348+0000] {logging_mixin.py:190} WARNING -   File "/home/***/.local/lib/python3.12/site-packages/***/utils/log/file_task_handler.py", line 274, in emit
    self.handler.emit(record)
[2024-10-28T21:15:54.348+0000] {logging_mixin.py:190} WARNING - Message: 'An error has occurred during load process for user_follow_stats. '
Arguments: (UniqueViolation('duplicate key value violates unique constraint "user_follow_stats_user_id_date_key"\nDETAIL:  Key (user_id, date)=(232192182, 2024-10-28 21:15:51) already exists.\nCONTEXT:  COPY user_follow_stats, line 2\n'),)
[2024-10-28T21:15:54.349+0000] {logging_mixin.py:190} INFO - ****************** Unexpected error: duplicate key value violates unique constraint "user_follow_stats_user_id_date_key"
DETAIL:  Key (user_id, date)=(232192182, 2024-10-28 21:15:51) already exists.
CONTEXT:  COPY user_follow_stats, line 2
[2024-10-28T21:15:54.349+0000] {logging_mixin.py:190} INFO -  (<class 'psycopg2.errors.UniqueViolation'>, UniqueViolation('duplicate key value violates unique constraint "user_follow_stats_user_id_date_key"\nDETAIL:  Key (user_id, date)=(232192182, 2024-10-28 21:15:51) already exists.\nCONTEXT:  COPY user_follow_stats, line 2\n'), <traceback object at 0x7b85407f1a40>)
[2024-10-28T21:15:54.349+0000] {taskinstance.py:3310} ERROR - Task failed with exception
Traceback (most recent call last):
  File "/home/airflow/.local/lib/python3.12/site-packages/airflow/models/taskinstance.py", line 767, in _execute_task
    result = _execute_callable(context=context, **execute_callable_kwargs)
             ^^^^^^^^^^^^^^^^^^^^^^^^^^^^^^^^^^^^^^^^^^^^^^^^^^^^^^^^^^^^^
  File "/home/airflow/.local/lib/python3.12/site-packages/airflow/models/taskinstance.py", line 733, in _execute_callable
    return ExecutionCallableRunner(
           ^^^^^^^^^^^^^^^^^^^^^^^^
  File "/home/airflow/.local/lib/python3.12/site-packages/airflow/utils/operator_helpers.py", line 252, in run
    return self.func(*args, **kwargs)
           ^^^^^^^^^^^^^^^^^^^^^^^^^^
  File "/home/airflow/.local/lib/python3.12/site-packages/airflow/models/baseoperator.py", line 406, in wrapper
    return func(self, *args, **kwargs)
           ^^^^^^^^^^^^^^^^^^^^^^^^^^^
  File "/home/airflow/.local/lib/python3.12/site-packages/airflow/operators/python.py", line 238, in execute
    return_value = self.execute_callable()
                   ^^^^^^^^^^^^^^^^^^^^^^^
  File "/home/airflow/.local/lib/python3.12/site-packages/airflow/operators/python.py", line 256, in execute_callable
    return runner.run(*self.op_args, **self.op_kwargs)
           ^^^^^^^^^^^^^^^^^^^^^^^^^^^^^^^^^^^^^^^^^^^
  File "/home/airflow/.local/lib/python3.12/site-packages/airflow/utils/operator_helpers.py", line 252, in run
    return self.func(*args, **kwargs)
           ^^^^^^^^^^^^^^^^^^^^^^^^^^
  File "/opt/airflow/dags/tab_social_media_refresh.py", line 12, in daily_instagram_stats
    pf.run()
  File "/opt/airflow/dags/src/social_media/evolution_stats_instagram.py", line 39, in run
    self.__load(
  File "/opt/airflow/dags/src/social_media/evolution_stats_instagram.py", line 109, in __load
    conn.execute_insert(
  File "/opt/airflow/dags/next_connection/data_connection.py", line 200, in execute_insert
    cursor.copy_expert(copy_cmd, string_data_io)
psycopg2.errors.UniqueViolation: duplicate key value violates unique constraint "user_follow_stats_user_id_date_key"
DETAIL:  Key (user_id, date)=(232192182, 2024-10-28 21:15:51) already exists.
CONTEXT:  COPY user_follow_stats, line 2

[2024-10-28T21:15:54.361+0000] {taskinstance.py:1225} INFO - Marking task as UP_FOR_RETRY. dag_id=tab_refresh_stats, task_id=daily_instagram_stats, run_id=manual__2024-10-28T21:15:42.467645+00:00, execution_date=20241028T211542, start_date=20241028T211544, end_date=20241028T211554
[2024-10-28T21:15:54.377+0000] {taskinstance.py:340} INFO - ::group::Post task execution logs
[2024-10-28T21:15:54.378+0000] {standard_task_runner.py:124} ERROR - Failed to execute job 14 for task daily_instagram_stats (duplicate key value violates unique constraint "user_follow_stats_user_id_date_key"
DETAIL:  Key (user_id, date)=(232192182, 2024-10-28 21:15:51) already exists.
CONTEXT:  COPY user_follow_stats, line 2
; 593)
Traceback (most recent call last):
  File "/home/airflow/.local/lib/python3.12/site-packages/airflow/task/task_runner/standard_task_runner.py", line 117, in _start_by_fork
    ret = args.func(args, dag=self.dag)
          ^^^^^^^^^^^^^^^^^^^^^^^^^^^^^
  File "/home/airflow/.local/lib/python3.12/site-packages/airflow/cli/cli_config.py", line 49, in command
    return func(*args, **kwargs)
           ^^^^^^^^^^^^^^^^^^^^^
  File "/home/airflow/.local/lib/python3.12/site-packages/airflow/utils/cli.py", line 115, in wrapper
    return f(*args, **kwargs)
           ^^^^^^^^^^^^^^^^^^
  File "/home/airflow/.local/lib/python3.12/site-packages/airflow/cli/commands/task_command.py", line 483, in task_run
    task_return_code = _run_task_by_selected_method(args, _dag, ti)
                       ^^^^^^^^^^^^^^^^^^^^^^^^^^^^^^^^^^^^^^^^^^^^
  File "/home/airflow/.local/lib/python3.12/site-packages/airflow/cli/commands/task_command.py", line 256, in _run_task_by_selected_method
    return _run_raw_task(args, ti)
           ^^^^^^^^^^^^^^^^^^^^^^^
  File "/home/airflow/.local/lib/python3.12/site-packages/airflow/cli/commands/task_command.py", line 341, in _run_raw_task
    return ti._run_raw_task(
           ^^^^^^^^^^^^^^^^^
  File "/home/airflow/.local/lib/python3.12/site-packages/airflow/utils/session.py", line 97, in wrapper
    return func(*args, session=session, **kwargs)
           ^^^^^^^^^^^^^^^^^^^^^^^^^^^^^^^^^^^^^^
  File "/home/airflow/.local/lib/python3.12/site-packages/airflow/models/taskinstance.py", line 3004, in _run_raw_task
    return _run_raw_task(
           ^^^^^^^^^^^^^^
  File "/home/airflow/.local/lib/python3.12/site-packages/airflow/models/taskinstance.py", line 273, in _run_raw_task
    TaskInstance._execute_task_with_callbacks(
  File "/home/airflow/.local/lib/python3.12/site-packages/airflow/models/taskinstance.py", line 3158, in _execute_task_with_callbacks
    result = self._execute_task(context, task_orig)
             ^^^^^^^^^^^^^^^^^^^^^^^^^^^^^^^^^^^^^^
  File "/home/airflow/.local/lib/python3.12/site-packages/airflow/models/taskinstance.py", line 3182, in _execute_task
    return _execute_task(self, context, task_orig)
           ^^^^^^^^^^^^^^^^^^^^^^^^^^^^^^^^^^^^^^^
  File "/home/airflow/.local/lib/python3.12/site-packages/airflow/models/taskinstance.py", line 767, in _execute_task
    result = _execute_callable(context=context, **execute_callable_kwargs)
             ^^^^^^^^^^^^^^^^^^^^^^^^^^^^^^^^^^^^^^^^^^^^^^^^^^^^^^^^^^^^^
  File "/home/airflow/.local/lib/python3.12/site-packages/airflow/models/taskinstance.py", line 733, in _execute_callable
    return ExecutionCallableRunner(
           ^^^^^^^^^^^^^^^^^^^^^^^^
  File "/home/airflow/.local/lib/python3.12/site-packages/airflow/utils/operator_helpers.py", line 252, in run
    return self.func(*args, **kwargs)
           ^^^^^^^^^^^^^^^^^^^^^^^^^^
  File "/home/airflow/.local/lib/python3.12/site-packages/airflow/models/baseoperator.py", line 406, in wrapper
    return func(self, *args, **kwargs)
           ^^^^^^^^^^^^^^^^^^^^^^^^^^^
  File "/home/airflow/.local/lib/python3.12/site-packages/airflow/operators/python.py", line 238, in execute
    return_value = self.execute_callable()
                   ^^^^^^^^^^^^^^^^^^^^^^^
  File "/home/airflow/.local/lib/python3.12/site-packages/airflow/operators/python.py", line 256, in execute_callable
    return runner.run(*self.op_args, **self.op_kwargs)
           ^^^^^^^^^^^^^^^^^^^^^^^^^^^^^^^^^^^^^^^^^^^
  File "/home/airflow/.local/lib/python3.12/site-packages/airflow/utils/operator_helpers.py", line 252, in run
    return self.func(*args, **kwargs)
           ^^^^^^^^^^^^^^^^^^^^^^^^^^
  File "/opt/airflow/dags/tab_social_media_refresh.py", line 12, in daily_instagram_stats
    pf.run()
  File "/opt/airflow/dags/src/social_media/evolution_stats_instagram.py", line 39, in run
    self.__load(
  File "/opt/airflow/dags/src/social_media/evolution_stats_instagram.py", line 109, in __load
    conn.execute_insert(
  File "/opt/airflow/dags/next_connection/data_connection.py", line 200, in execute_insert
    cursor.copy_expert(copy_cmd, string_data_io)
psycopg2.errors.UniqueViolation: duplicate key value violates unique constraint "user_follow_stats_user_id_date_key"
DETAIL:  Key (user_id, date)=(232192182, 2024-10-28 21:15:51) already exists.
CONTEXT:  COPY user_follow_stats, line 2

[2024-10-28T21:15:54.396+0000] {local_task_job_runner.py:266} INFO - Task exited with return code 1
[2024-10-28T21:15:54.408+0000] {taskinstance.py:3900} INFO - 0 downstream tasks scheduled from follow-on schedule check
[2024-10-28T21:15:54.409+0000] {local_task_job_runner.py:245} INFO - ::endgroup::
