[2024-09-30T14:32:09.009+0000] {local_task_job_runner.py:123} INFO - ::group::Pre task execution logs
[2024-09-30T14:32:09.021+0000] {taskinstance.py:2612} INFO - Dependencies all met for dep_context=non-requeueable deps ti=<TaskInstance: tab_soccer_statics.fact_matches_statistics manual__2024-09-30T14:31:47.119862+00:00 [queued]>
[2024-09-30T14:32:09.026+0000] {taskinstance.py:2612} INFO - Dependencies all met for dep_context=requeueable deps ti=<TaskInstance: tab_soccer_statics.fact_matches_statistics manual__2024-09-30T14:31:47.119862+00:00 [queued]>
[2024-09-30T14:32:09.027+0000] {taskinstance.py:2865} INFO - Starting attempt 1 of 2
[2024-09-30T14:32:09.036+0000] {taskinstance.py:2888} INFO - Executing <Task(PythonOperator): fact_matches_statistics> on 2024-09-30 14:31:47.119862+00:00
[2024-09-30T14:32:09.045+0000] {warnings.py:112} WARNING - /home/***/.local/lib/python3.12/site-packages/***/task/task_runner/standard_task_runner.py:70: DeprecationWarning: This process (pid=4223) is multi-threaded, use of fork() may lead to deadlocks in the child.
  pid = os.fork()

[2024-09-30T14:32:09.047+0000] {standard_task_runner.py:72} INFO - Started process 4236 to run task
[2024-09-30T14:32:09.047+0000] {standard_task_runner.py:104} INFO - Running: ['***', 'tasks', 'run', 'tab_soccer_statics', 'fact_matches_statistics', 'manual__2024-09-30T14:31:47.119862+00:00', '--job-id', '178', '--raw', '--subdir', 'DAGS_FOLDER/tab_soccer_statics.py', '--cfg-path', '/tmp/tmpr5_zxwzv']
[2024-09-30T14:32:09.049+0000] {standard_task_runner.py:105} INFO - Job 178: Subtask fact_matches_statistics
[2024-09-30T14:32:09.082+0000] {task_command.py:467} INFO - Running <TaskInstance: tab_soccer_statics.fact_matches_statistics manual__2024-09-30T14:31:47.119862+00:00 [running]> on host 58fa97ed942d
[2024-09-30T14:32:09.151+0000] {taskinstance.py:3131} INFO - Exporting env vars: AIRFLOW_CTX_DAG_OWNER='daniel.cristancho' AIRFLOW_CTX_DAG_ID='tab_soccer_statics' AIRFLOW_CTX_TASK_ID='fact_matches_statistics' AIRFLOW_CTX_EXECUTION_DATE='2024-09-30T14:31:47.119862+00:00' AIRFLOW_CTX_TRY_NUMBER='1' AIRFLOW_CTX_DAG_RUN_ID='manual__2024-09-30T14:31:47.119862+00:00'
[2024-09-30T14:32:09.151+0000] {taskinstance.py:731} INFO - ::endgroup::
[2024-09-30T14:32:10.837+0000] {fact_matches_statics.py:32} INFO - Start extract loaded data
[2024-09-30T14:32:10.837+0000] {fact_matches_statics.py:185} INFO - Staring data extraction for dim_teams
[2024-09-30T14:32:12.345+0000] {fact_matches_statics.py:189} INFO - 80 rows extracted from dim_teams
[2024-09-30T14:32:12.345+0000] {fact_matches_statics.py:190} INFO - Data extraction successfully finished
[2024-09-30T14:32:12.346+0000] {fact_matches_statics.py:185} INFO - Staring data extraction for fact_matches_statistics
[2024-09-30T14:32:12.661+0000] {logging_mixin.py:190} WARNING - --- Logging error ---
[2024-09-30T14:32:12.674+0000] {logging_mixin.py:190} WARNING - Traceback (most recent call last):
[2024-09-30T14:32:12.675+0000] {logging_mixin.py:190} WARNING -   File "/home/***/.local/lib/python3.12/site-packages/sqlalchemy/engine/base.py", line 1910, in _execute_context
    self.dialect.do_execute(
[2024-09-30T14:32:12.675+0000] {logging_mixin.py:190} WARNING -   File "/home/***/.local/lib/python3.12/site-packages/sqlalchemy/engine/default.py", line 736, in do_execute
    cursor.execute(statement, parameters)
[2024-09-30T14:32:12.675+0000] {logging_mixin.py:190} WARNING - psycopg2.errors.InvalidColumnReference: ORDER BY position 30 is not in select list
LINE 6: ORDER BY 30 DESC
                 ^
[2024-09-30T14:32:12.676+0000] {logging_mixin.py:190} WARNING - 
The above exception was the direct cause of the following exception:
[2024-09-30T14:32:12.676+0000] {logging_mixin.py:190} WARNING - Traceback (most recent call last):
[2024-09-30T14:32:12.676+0000] {logging_mixin.py:190} WARNING -   File "/opt/***/dags/src/soccer_statics/fact_matches_statics.py", line 188, in __extract
    data = pd.read_sql(query, conn_name.connection, params=params)
           ^^^^^^^^^^^^^^^^^^^^^^^^^^^^^^^^^^^^^^^^^^^^^^^^^^^^^^^
[2024-09-30T14:32:12.676+0000] {logging_mixin.py:190} WARNING -   File "/home/***/.local/lib/python3.12/site-packages/pandas/io/sql.py", line 682, in read_sql
    return pandas_sql.read_query(
           ^^^^^^^^^^^^^^^^^^^^^^
[2024-09-30T14:32:12.677+0000] {logging_mixin.py:190} WARNING -   File "/home/***/.local/lib/python3.12/site-packages/pandas/io/sql.py", line 1776, in read_query
    result = self.execute(sql, params)
             ^^^^^^^^^^^^^^^^^^^^^^^^^
[2024-09-30T14:32:12.677+0000] {logging_mixin.py:190} WARNING -   File "/home/***/.local/lib/python3.12/site-packages/pandas/io/sql.py", line 1599, in execute
    return self.con.exec_driver_sql(sql, *args)
           ^^^^^^^^^^^^^^^^^^^^^^^^^^^^^^^^^^^^
[2024-09-30T14:32:12.677+0000] {logging_mixin.py:190} WARNING -   File "/home/***/.local/lib/python3.12/site-packages/sqlalchemy/engine/base.py", line 1770, in exec_driver_sql
    return self._exec_driver_sql(
           ^^^^^^^^^^^^^^^^^^^^^^
[2024-09-30T14:32:12.677+0000] {logging_mixin.py:190} WARNING -   File "/home/***/.local/lib/python3.12/site-packages/sqlalchemy/engine/base.py", line 1674, in _exec_driver_sql
    ret = self._execute_context(
          ^^^^^^^^^^^^^^^^^^^^^^
[2024-09-30T14:32:12.678+0000] {logging_mixin.py:190} WARNING -   File "/home/***/.local/lib/python3.12/site-packages/sqlalchemy/engine/base.py", line 1953, in _execute_context
    self._handle_dbapi_exception(
[2024-09-30T14:32:12.678+0000] {logging_mixin.py:190} WARNING -   File "/home/***/.local/lib/python3.12/site-packages/sqlalchemy/engine/base.py", line 2134, in _handle_dbapi_exception
    util.raise_(
[2024-09-30T14:32:12.678+0000] {logging_mixin.py:190} WARNING -   File "/home/***/.local/lib/python3.12/site-packages/sqlalchemy/util/compat.py", line 211, in raise_
    raise exception
[2024-09-30T14:32:12.678+0000] {logging_mixin.py:190} WARNING -   File "/home/***/.local/lib/python3.12/site-packages/sqlalchemy/engine/base.py", line 1910, in _execute_context
    self.dialect.do_execute(
[2024-09-30T14:32:12.679+0000] {logging_mixin.py:190} WARNING -   File "/home/***/.local/lib/python3.12/site-packages/sqlalchemy/engine/default.py", line 736, in do_execute
    cursor.execute(statement, parameters)
[2024-09-30T14:32:12.679+0000] {logging_mixin.py:190} WARNING - sqlalchemy.exc.ProgrammingError: (psycopg2.errors.InvalidColumnReference) ORDER BY position 30 is not in select list
LINE 6: ORDER BY 30 DESC
                 ^

[SQL: 
SELECT id_match,date_match,fm."uuid"
FROM soccer.fact_matches fm 
LEFT JOIN soccer.fact_matches_statistics fms ON fm."uuid" = fms.uuid_match 
WHERE fms."uuid" IS NULL
ORDER BY 30 DESC
LIMIT 1
]
(Background on this error at: https://sqlalche.me/e/14/f405)
[2024-09-30T14:32:12.679+0000] {logging_mixin.py:190} WARNING - 
During handling of the above exception, another exception occurred:
[2024-09-30T14:32:12.679+0000] {logging_mixin.py:190} WARNING - Traceback (most recent call last):
[2024-09-30T14:32:12.680+0000] {logging_mixin.py:190} WARNING -   File "/usr/local/lib/python3.12/logging/__init__.py", line 1160, in emit
    msg = self.format(record)
          ^^^^^^^^^^^^^^^^^^^
[2024-09-30T14:32:12.680+0000] {logging_mixin.py:190} WARNING -   File "/usr/local/lib/python3.12/logging/__init__.py", line 999, in format
    return fmt.format(record)
           ^^^^^^^^^^^^^^^^^^
[2024-09-30T14:32:12.680+0000] {logging_mixin.py:190} WARNING -   File "/usr/local/lib/python3.12/logging/__init__.py", line 703, in format
    record.message = record.getMessage()
                     ^^^^^^^^^^^^^^^^^^^
[2024-09-30T14:32:12.680+0000] {logging_mixin.py:190} WARNING -   File "/usr/local/lib/python3.12/logging/__init__.py", line 392, in getMessage
    msg = msg % self.args
          ~~~~^~~~~~~~~~~
[2024-09-30T14:32:12.681+0000] {logging_mixin.py:190} WARNING - TypeError: not all arguments converted during string formatting
[2024-09-30T14:32:12.681+0000] {logging_mixin.py:190} WARNING - Call stack:
[2024-09-30T14:32:12.693+0000] {logging_mixin.py:190} WARNING -   File "/home/***/.local/bin/***", line 8, in <module>
    sys.exit(main())
[2024-09-30T14:32:12.694+0000] {logging_mixin.py:190} WARNING -   File "/home/***/.local/lib/python3.12/site-packages/***/__main__.py", line 62, in main
    args.func(args)
[2024-09-30T14:32:12.694+0000] {logging_mixin.py:190} WARNING -   File "/home/***/.local/lib/python3.12/site-packages/***/cli/cli_config.py", line 49, in command
    return func(*args, **kwargs)
[2024-09-30T14:32:12.694+0000] {logging_mixin.py:190} WARNING -   File "/home/***/.local/lib/python3.12/site-packages/***/utils/cli.py", line 115, in wrapper
    return f(*args, **kwargs)
[2024-09-30T14:32:12.694+0000] {logging_mixin.py:190} WARNING -   File "/home/***/.local/lib/python3.12/site-packages/***/providers/celery/cli/celery_command.py", line 61, in wrapper
    providers_configuration_loaded(func)(*args, **kwargs)
[2024-09-30T14:32:12.695+0000] {logging_mixin.py:190} WARNING -   File "/home/***/.local/lib/python3.12/site-packages/***/utils/providers_configuration_loader.py", line 55, in wrapped_function
    return func(*args, **kwargs)
[2024-09-30T14:32:12.695+0000] {logging_mixin.py:190} WARNING -   File "/home/***/.local/lib/python3.12/site-packages/***/providers/celery/cli/celery_command.py", line 234, in worker
    _run_command_with_daemon_option(
[2024-09-30T14:32:12.695+0000] {logging_mixin.py:190} WARNING -   File "/home/***/.local/lib/python3.12/site-packages/***/providers/celery/cli/celery_command.py", line 47, in _run_command_with_daemon_option
    run_command_with_daemon_option(*args, **kwargs)
[2024-09-30T14:32:12.695+0000] {logging_mixin.py:190} WARNING -   File "/home/***/.local/lib/python3.12/site-packages/***/cli/commands/daemon_utils.py", line 86, in run_command_with_daemon_option
    callback()
[2024-09-30T14:32:12.696+0000] {logging_mixin.py:190} WARNING -   File "/home/***/.local/lib/python3.12/site-packages/***/providers/celery/cli/celery_command.py", line 227, in run_celery_worker
    celery_app.worker_main(options)
[2024-09-30T14:32:12.696+0000] {logging_mixin.py:190} WARNING -   File "/home/***/.local/lib/python3.12/site-packages/celery/app/base.py", line 391, in worker_main
    self.start(argv=argv)
[2024-09-30T14:32:12.696+0000] {logging_mixin.py:190} WARNING -   File "/home/***/.local/lib/python3.12/site-packages/celery/app/base.py", line 371, in start
    celery.main(args=argv, standalone_mode=False)
[2024-09-30T14:32:12.696+0000] {logging_mixin.py:190} WARNING -   File "/home/***/.local/lib/python3.12/site-packages/click/core.py", line 1078, in main
    rv = self.invoke(ctx)
[2024-09-30T14:32:12.696+0000] {logging_mixin.py:190} WARNING -   File "/home/***/.local/lib/python3.12/site-packages/click/core.py", line 1688, in invoke
    return _process_result(sub_ctx.command.invoke(sub_ctx))
[2024-09-30T14:32:12.697+0000] {logging_mixin.py:190} WARNING -   File "/home/***/.local/lib/python3.12/site-packages/click/core.py", line 1434, in invoke
    return ctx.invoke(self.callback, **ctx.params)
[2024-09-30T14:32:12.697+0000] {logging_mixin.py:190} WARNING -   File "/home/***/.local/lib/python3.12/site-packages/click/core.py", line 783, in invoke
    return __callback(*args, **kwargs)
[2024-09-30T14:32:12.697+0000] {logging_mixin.py:190} WARNING -   File "/home/***/.local/lib/python3.12/site-packages/click/decorators.py", line 33, in new_func
    return f(get_current_context(), *args, **kwargs)
[2024-09-30T14:32:12.697+0000] {logging_mixin.py:190} WARNING -   File "/home/***/.local/lib/python3.12/site-packages/celery/bin/base.py", line 135, in caller
    return f(ctx, *args, **kwargs)
[2024-09-30T14:32:12.697+0000] {logging_mixin.py:190} WARNING -   File "/home/***/.local/lib/python3.12/site-packages/celery/bin/worker.py", line 356, in worker
    worker.start()
[2024-09-30T14:32:12.698+0000] {logging_mixin.py:190} WARNING -   File "/home/***/.local/lib/python3.12/site-packages/celery/worker/worker.py", line 202, in start
    self.blueprint.start(self)
[2024-09-30T14:32:12.698+0000] {logging_mixin.py:190} WARNING -   File "/home/***/.local/lib/python3.12/site-packages/celery/bootsteps.py", line 116, in start
    step.start(parent)
[2024-09-30T14:32:12.698+0000] {logging_mixin.py:190} WARNING -   File "/home/***/.local/lib/python3.12/site-packages/celery/bootsteps.py", line 365, in start
    return self.obj.start()
[2024-09-30T14:32:12.698+0000] {logging_mixin.py:190} WARNING -   File "/home/***/.local/lib/python3.12/site-packages/celery/concurrency/base.py", line 130, in start
    self.on_start()
[2024-09-30T14:32:12.698+0000] {logging_mixin.py:190} WARNING -   File "/home/***/.local/lib/python3.12/site-packages/celery/concurrency/prefork.py", line 109, in on_start
    P = self._pool = Pool(processes=self.limit,
[2024-09-30T14:32:12.699+0000] {logging_mixin.py:190} WARNING -   File "/home/***/.local/lib/python3.12/site-packages/celery/concurrency/asynpool.py", line 464, in __init__
    super().__init__(processes, *args, **kwargs)
[2024-09-30T14:32:12.699+0000] {logging_mixin.py:190} WARNING -   File "/home/***/.local/lib/python3.12/site-packages/billiard/pool.py", line 1045, in __init__
    self._create_worker_process(i)
[2024-09-30T14:32:12.699+0000] {logging_mixin.py:190} WARNING -   File "/home/***/.local/lib/python3.12/site-packages/celery/concurrency/asynpool.py", line 482, in _create_worker_process
    return super()._create_worker_process(i)
[2024-09-30T14:32:12.699+0000] {logging_mixin.py:190} WARNING -   File "/home/***/.local/lib/python3.12/site-packages/billiard/pool.py", line 1157, in _create_worker_process
    w.start()
[2024-09-30T14:32:12.699+0000] {logging_mixin.py:190} WARNING -   File "/home/***/.local/lib/python3.12/site-packages/billiard/process.py", line 120, in start
    self._popen = self._Popen(self)
[2024-09-30T14:32:12.700+0000] {logging_mixin.py:190} WARNING -   File "/home/***/.local/lib/python3.12/site-packages/billiard/context.py", line 331, in _Popen
    return Popen(process_obj)
[2024-09-30T14:32:12.700+0000] {logging_mixin.py:190} WARNING -   File "/home/***/.local/lib/python3.12/site-packages/billiard/popen_fork.py", line 22, in __init__
    self._launch(process_obj)
[2024-09-30T14:32:12.700+0000] {logging_mixin.py:190} WARNING -   File "/home/***/.local/lib/python3.12/site-packages/billiard/popen_fork.py", line 77, in _launch
    code = process_obj._bootstrap()
[2024-09-30T14:32:12.700+0000] {logging_mixin.py:190} WARNING -   File "/home/***/.local/lib/python3.12/site-packages/billiard/process.py", line 323, in _bootstrap
    self.run()
[2024-09-30T14:32:12.700+0000] {logging_mixin.py:190} WARNING -   File "/home/***/.local/lib/python3.12/site-packages/billiard/process.py", line 110, in run
    self._target(*self._args, **self._kwargs)
[2024-09-30T14:32:12.701+0000] {logging_mixin.py:190} WARNING -   File "/home/***/.local/lib/python3.12/site-packages/billiard/pool.py", line 291, in __call__
    sys.exit(self.workloop(pid=pid))
[2024-09-30T14:32:12.701+0000] {logging_mixin.py:190} WARNING -   File "/home/***/.local/lib/python3.12/site-packages/billiard/pool.py", line 361, in workloop
    result = (True, prepare_result(fun(*args, **kwargs)))
[2024-09-30T14:32:12.701+0000] {logging_mixin.py:190} WARNING -   File "/home/***/.local/lib/python3.12/site-packages/celery/app/trace.py", line 651, in fast_trace_task
    R, I, T, Rstr = tasks[task].__trace__(
[2024-09-30T14:32:12.701+0000] {logging_mixin.py:190} WARNING -   File "/home/***/.local/lib/python3.12/site-packages/celery/app/trace.py", line 453, in trace_task
    R = retval = fun(*args, **kwargs)
[2024-09-30T14:32:12.701+0000] {logging_mixin.py:190} WARNING -   File "/home/***/.local/lib/python3.12/site-packages/celery/app/trace.py", line 736, in __protected_call__
    return self.run(*args, **kwargs)
[2024-09-30T14:32:12.702+0000] {logging_mixin.py:190} WARNING -   File "/home/***/.local/lib/python3.12/site-packages/***/providers/celery/executors/celery_executor_utils.py", line 135, in execute_command
    _execute_in_fork(command_to_exec, celery_task_id)
[2024-09-30T14:32:12.702+0000] {logging_mixin.py:190} WARNING -   File "/home/***/.local/lib/python3.12/site-packages/***/providers/celery/executors/celery_executor_utils.py", line 171, in _execute_in_fork
    args.func(args)
[2024-09-30T14:32:12.702+0000] {logging_mixin.py:190} WARNING -   File "/home/***/.local/lib/python3.12/site-packages/***/cli/cli_config.py", line 49, in command
    return func(*args, **kwargs)
[2024-09-30T14:32:12.702+0000] {logging_mixin.py:190} WARNING -   File "/home/***/.local/lib/python3.12/site-packages/***/utils/cli.py", line 115, in wrapper
    return f(*args, **kwargs)
[2024-09-30T14:32:12.702+0000] {logging_mixin.py:190} WARNING -   File "/home/***/.local/lib/python3.12/site-packages/***/cli/commands/task_command.py", line 483, in task_run
    task_return_code = _run_task_by_selected_method(args, _dag, ti)
[2024-09-30T14:32:12.703+0000] {logging_mixin.py:190} WARNING -   File "/home/***/.local/lib/python3.12/site-packages/***/cli/commands/task_command.py", line 254, in _run_task_by_selected_method
    return _run_task_by_local_task_job(args, ti)
[2024-09-30T14:32:12.703+0000] {logging_mixin.py:190} WARNING -   File "/home/***/.local/lib/python3.12/site-packages/***/cli/commands/task_command.py", line 322, in _run_task_by_local_task_job
    ret = run_job(job=job_runner.job, execute_callable=job_runner._execute)
[2024-09-30T14:32:12.703+0000] {logging_mixin.py:190} WARNING -   File "/home/***/.local/lib/python3.12/site-packages/***/utils/session.py", line 97, in wrapper
    return func(*args, session=session, **kwargs)
[2024-09-30T14:32:12.703+0000] {logging_mixin.py:190} WARNING -   File "/home/***/.local/lib/python3.12/site-packages/***/jobs/job.py", line 421, in run_job
    return execute_job(job, execute_callable=execute_callable)
[2024-09-30T14:32:12.703+0000] {logging_mixin.py:190} WARNING -   File "/home/***/.local/lib/python3.12/site-packages/***/jobs/job.py", line 450, in execute_job
    ret = execute_callable()
[2024-09-30T14:32:12.704+0000] {logging_mixin.py:190} WARNING -   File "/home/***/.local/lib/python3.12/site-packages/***/jobs/local_task_job_runner.py", line 171, in _execute
    self.task_runner.start()
[2024-09-30T14:32:12.704+0000] {logging_mixin.py:190} WARNING -   File "/home/***/.local/lib/python3.12/site-packages/***/task/task_runner/standard_task_runner.py", line 55, in start
    self.process = self._start_by_fork()
[2024-09-30T14:32:12.704+0000] {logging_mixin.py:190} WARNING -   File "/home/***/.local/lib/python3.12/site-packages/***/task/task_runner/standard_task_runner.py", line 117, in _start_by_fork
    ret = args.func(args, dag=self.dag)
[2024-09-30T14:32:12.704+0000] {logging_mixin.py:190} WARNING -   File "/home/***/.local/lib/python3.12/site-packages/***/cli/cli_config.py", line 49, in command
    return func(*args, **kwargs)
[2024-09-30T14:32:12.704+0000] {logging_mixin.py:190} WARNING -   File "/home/***/.local/lib/python3.12/site-packages/***/utils/cli.py", line 115, in wrapper
    return f(*args, **kwargs)
[2024-09-30T14:32:12.705+0000] {logging_mixin.py:190} WARNING -   File "/home/***/.local/lib/python3.12/site-packages/***/cli/commands/task_command.py", line 483, in task_run
    task_return_code = _run_task_by_selected_method(args, _dag, ti)
[2024-09-30T14:32:12.705+0000] {logging_mixin.py:190} WARNING -   File "/home/***/.local/lib/python3.12/site-packages/***/cli/commands/task_command.py", line 256, in _run_task_by_selected_method
    return _run_raw_task(args, ti)
[2024-09-30T14:32:12.705+0000] {logging_mixin.py:190} WARNING -   File "/home/***/.local/lib/python3.12/site-packages/***/cli/commands/task_command.py", line 341, in _run_raw_task
    return ti._run_raw_task(
[2024-09-30T14:32:12.705+0000] {logging_mixin.py:190} WARNING -   File "/home/***/.local/lib/python3.12/site-packages/***/utils/session.py", line 97, in wrapper
    return func(*args, session=session, **kwargs)
[2024-09-30T14:32:12.705+0000] {logging_mixin.py:190} WARNING -   File "/home/***/.local/lib/python3.12/site-packages/***/models/taskinstance.py", line 3004, in _run_raw_task
    return _run_raw_task(
[2024-09-30T14:32:12.706+0000] {logging_mixin.py:190} WARNING -   File "/home/***/.local/lib/python3.12/site-packages/***/models/taskinstance.py", line 273, in _run_raw_task
    TaskInstance._execute_task_with_callbacks(
[2024-09-30T14:32:12.706+0000] {logging_mixin.py:190} WARNING -   File "/home/***/.local/lib/python3.12/site-packages/***/models/taskinstance.py", line 3158, in _execute_task_with_callbacks
    result = self._execute_task(context, task_orig)
[2024-09-30T14:32:12.706+0000] {logging_mixin.py:190} WARNING -   File "/home/***/.local/lib/python3.12/site-packages/***/models/taskinstance.py", line 3182, in _execute_task
    return _execute_task(self, context, task_orig)
[2024-09-30T14:32:12.706+0000] {logging_mixin.py:190} WARNING -   File "/home/***/.local/lib/python3.12/site-packages/***/models/taskinstance.py", line 767, in _execute_task
    result = _execute_callable(context=context, **execute_callable_kwargs)
[2024-09-30T14:32:12.706+0000] {logging_mixin.py:190} WARNING -   File "/home/***/.local/lib/python3.12/site-packages/***/models/taskinstance.py", line 733, in _execute_callable
    return ExecutionCallableRunner(
[2024-09-30T14:32:12.707+0000] {logging_mixin.py:190} WARNING -   File "/home/***/.local/lib/python3.12/site-packages/***/utils/operator_helpers.py", line 252, in run
    return self.func(*args, **kwargs)
[2024-09-30T14:32:12.707+0000] {logging_mixin.py:190} WARNING -   File "/home/***/.local/lib/python3.12/site-packages/***/models/baseoperator.py", line 406, in wrapper
    return func(self, *args, **kwargs)
[2024-09-30T14:32:12.707+0000] {logging_mixin.py:190} WARNING -   File "/home/***/.local/lib/python3.12/site-packages/***/operators/python.py", line 238, in execute
    return_value = self.execute_callable()
[2024-09-30T14:32:12.707+0000] {logging_mixin.py:190} WARNING -   File "/home/***/.local/lib/python3.12/site-packages/***/operators/python.py", line 256, in execute_callable
    return runner.run(*self.op_args, **self.op_kwargs)
[2024-09-30T14:32:12.708+0000] {logging_mixin.py:190} WARNING -   File "/home/***/.local/lib/python3.12/site-packages/***/utils/operator_helpers.py", line 252, in run
    return self.func(*args, **kwargs)
[2024-09-30T14:32:12.708+0000] {logging_mixin.py:190} WARNING -   File "/opt/***/dags/tab_soccer_statics.py", line 83, in fact_matches_statistics
    pf.run()
[2024-09-30T14:32:12.708+0000] {logging_mixin.py:190} WARNING -   File "/opt/***/dags/src/soccer_statics/fact_matches_statics.py", line 37, in run
    data["fact_matches"] = self.__extract(
[2024-09-30T14:32:12.708+0000] {logging_mixin.py:190} WARNING -   File "/opt/***/dags/src/soccer_statics/fact_matches_statics.py", line 192, in __extract
    self.__logger.error("An error has occurred during data extraction. ", e)
[2024-09-30T14:32:12.708+0000] {logging_mixin.py:190} WARNING -   File "/usr/local/lib/python3.12/logging/__init__.py", line 1568, in error
    self._log(ERROR, msg, args, **kwargs)
[2024-09-30T14:32:12.709+0000] {logging_mixin.py:190} WARNING -   File "/usr/local/lib/python3.12/logging/__init__.py", line 1684, in _log
    self.handle(record)
[2024-09-30T14:32:12.709+0000] {logging_mixin.py:190} WARNING -   File "/usr/local/lib/python3.12/logging/__init__.py", line 1700, in handle
    self.callHandlers(record)
[2024-09-30T14:32:12.709+0000] {logging_mixin.py:190} WARNING -   File "/usr/local/lib/python3.12/logging/__init__.py", line 1762, in callHandlers
    hdlr.handle(record)
[2024-09-30T14:32:12.709+0000] {logging_mixin.py:190} WARNING -   File "/usr/local/lib/python3.12/logging/__init__.py", line 1028, in handle
    self.emit(record)
[2024-09-30T14:32:12.709+0000] {logging_mixin.py:190} WARNING -   File "/home/***/.local/lib/python3.12/site-packages/***/utils/log/file_task_handler.py", line 274, in emit
    self.handler.emit(record)
[2024-09-30T14:32:12.710+0000] {logging_mixin.py:190} WARNING - Message: 'An error has occurred during data extraction. '
Arguments: (ProgrammingError('(psycopg2.errors.InvalidColumnReference) ORDER BY position 30 is not in select list\nLINE 6: ORDER BY 30 DESC\n                 ^\n'),)
[2024-09-30T14:32:12.710+0000] {logging_mixin.py:190} INFO - ****************** Unexpected error update fact matches statistics:  (<class 'sqlalchemy.exc.ProgrammingError'>, ProgrammingError('(psycopg2.errors.InvalidColumnReference) ORDER BY position 30 is not in select list\nLINE 6: ORDER BY 30 DESC\n                 ^\n'), <traceback object at 0x7299d7d43ec0>)
[2024-09-30T14:32:12.710+0000] {taskinstance.py:3310} ERROR - Task failed with exception
Traceback (most recent call last):
  File "/home/airflow/.local/lib/python3.12/site-packages/sqlalchemy/engine/base.py", line 1910, in _execute_context
    self.dialect.do_execute(
  File "/home/airflow/.local/lib/python3.12/site-packages/sqlalchemy/engine/default.py", line 736, in do_execute
    cursor.execute(statement, parameters)
psycopg2.errors.InvalidColumnReference: ORDER BY position 30 is not in select list
LINE 6: ORDER BY 30 DESC
                 ^


The above exception was the direct cause of the following exception:

Traceback (most recent call last):
  File "/home/airflow/.local/lib/python3.12/site-packages/airflow/models/taskinstance.py", line 767, in _execute_task
    result = _execute_callable(context=context, **execute_callable_kwargs)
             ^^^^^^^^^^^^^^^^^^^^^^^^^^^^^^^^^^^^^^^^^^^^^^^^^^^^^^^^^^^^^
  File "/home/airflow/.local/lib/python3.12/site-packages/airflow/models/taskinstance.py", line 733, in _execute_callable
    return ExecutionCallableRunner(
           ^^^^^^^^^^^^^^^^^^^^^^^^
  File "/home/airflow/.local/lib/python3.12/site-packages/airflow/utils/operator_helpers.py", line 252, in run
    return self.func(*args, **kwargs)
           ^^^^^^^^^^^^^^^^^^^^^^^^^^
  File "/home/airflow/.local/lib/python3.12/site-packages/airflow/models/baseoperator.py", line 406, in wrapper
    return func(self, *args, **kwargs)
           ^^^^^^^^^^^^^^^^^^^^^^^^^^^
  File "/home/airflow/.local/lib/python3.12/site-packages/airflow/operators/python.py", line 238, in execute
    return_value = self.execute_callable()
                   ^^^^^^^^^^^^^^^^^^^^^^^
  File "/home/airflow/.local/lib/python3.12/site-packages/airflow/operators/python.py", line 256, in execute_callable
    return runner.run(*self.op_args, **self.op_kwargs)
           ^^^^^^^^^^^^^^^^^^^^^^^^^^^^^^^^^^^^^^^^^^^
  File "/home/airflow/.local/lib/python3.12/site-packages/airflow/utils/operator_helpers.py", line 252, in run
    return self.func(*args, **kwargs)
           ^^^^^^^^^^^^^^^^^^^^^^^^^^
  File "/opt/airflow/dags/tab_soccer_statics.py", line 83, in fact_matches_statistics
    pf.run()
  File "/opt/airflow/dags/src/soccer_statics/fact_matches_statics.py", line 37, in run
    data["fact_matches"] = self.__extract(
                           ^^^^^^^^^^^^^^^
  File "/opt/airflow/dags/src/soccer_statics/fact_matches_statics.py", line 188, in __extract
    data = pd.read_sql(query, conn_name.connection, params=params)
           ^^^^^^^^^^^^^^^^^^^^^^^^^^^^^^^^^^^^^^^^^^^^^^^^^^^^^^^
  File "/home/airflow/.local/lib/python3.12/site-packages/pandas/io/sql.py", line 682, in read_sql
    return pandas_sql.read_query(
           ^^^^^^^^^^^^^^^^^^^^^^
  File "/home/airflow/.local/lib/python3.12/site-packages/pandas/io/sql.py", line 1776, in read_query
    result = self.execute(sql, params)
             ^^^^^^^^^^^^^^^^^^^^^^^^^
  File "/home/airflow/.local/lib/python3.12/site-packages/pandas/io/sql.py", line 1599, in execute
    return self.con.exec_driver_sql(sql, *args)
           ^^^^^^^^^^^^^^^^^^^^^^^^^^^^^^^^^^^^
  File "/home/airflow/.local/lib/python3.12/site-packages/sqlalchemy/engine/base.py", line 1770, in exec_driver_sql
    return self._exec_driver_sql(
           ^^^^^^^^^^^^^^^^^^^^^^
  File "/home/airflow/.local/lib/python3.12/site-packages/sqlalchemy/engine/base.py", line 1674, in _exec_driver_sql
    ret = self._execute_context(
          ^^^^^^^^^^^^^^^^^^^^^^
  File "/home/airflow/.local/lib/python3.12/site-packages/sqlalchemy/engine/base.py", line 1953, in _execute_context
    self._handle_dbapi_exception(
  File "/home/airflow/.local/lib/python3.12/site-packages/sqlalchemy/engine/base.py", line 2134, in _handle_dbapi_exception
    util.raise_(
  File "/home/airflow/.local/lib/python3.12/site-packages/sqlalchemy/util/compat.py", line 211, in raise_
    raise exception
  File "/home/airflow/.local/lib/python3.12/site-packages/sqlalchemy/engine/base.py", line 1910, in _execute_context
    self.dialect.do_execute(
  File "/home/airflow/.local/lib/python3.12/site-packages/sqlalchemy/engine/default.py", line 736, in do_execute
    cursor.execute(statement, parameters)
sqlalchemy.exc.ProgrammingError: (psycopg2.errors.InvalidColumnReference) ORDER BY position 30 is not in select list
LINE 6: ORDER BY 30 DESC
                 ^

[SQL: 
SELECT id_match,date_match,fm."uuid"
FROM soccer.fact_matches fm 
LEFT JOIN soccer.fact_matches_statistics fms ON fm."uuid" = fms.uuid_match 
WHERE fms."uuid" IS NULL
ORDER BY 30 DESC
LIMIT 1
]
(Background on this error at: https://sqlalche.me/e/14/f405)
[2024-09-30T14:32:12.721+0000] {taskinstance.py:1225} INFO - Marking task as UP_FOR_RETRY. dag_id=tab_soccer_statics, task_id=fact_matches_statistics, run_id=manual__2024-09-30T14:31:47.119862+00:00, execution_date=20240930T143147, start_date=20240930T143209, end_date=20240930T143212
[2024-09-30T14:32:12.732+0000] {taskinstance.py:340} INFO - ::group::Post task execution logs
[2024-09-30T14:32:12.733+0000] {standard_task_runner.py:124} ERROR - Failed to execute job 178 for task fact_matches_statistics ((psycopg2.errors.InvalidColumnReference) ORDER BY position 30 is not in select list
LINE 6: ORDER BY 30 DESC
                 ^

[SQL: 
SELECT id_match,date_match,fm."uuid"
FROM soccer.fact_matches fm 
LEFT JOIN soccer.fact_matches_statistics fms ON fm."uuid" = fms.uuid_match 
WHERE fms."uuid" IS NULL
ORDER BY 30 DESC
LIMIT 1
]
(Background on this error at: https://sqlalche.me/e/14/f405); 4236)
Traceback (most recent call last):
  File "/home/airflow/.local/lib/python3.12/site-packages/sqlalchemy/engine/base.py", line 1910, in _execute_context
    self.dialect.do_execute(
  File "/home/airflow/.local/lib/python3.12/site-packages/sqlalchemy/engine/default.py", line 736, in do_execute
    cursor.execute(statement, parameters)
psycopg2.errors.InvalidColumnReference: ORDER BY position 30 is not in select list
LINE 6: ORDER BY 30 DESC
                 ^


The above exception was the direct cause of the following exception:

Traceback (most recent call last):
  File "/home/airflow/.local/lib/python3.12/site-packages/airflow/task/task_runner/standard_task_runner.py", line 117, in _start_by_fork
    ret = args.func(args, dag=self.dag)
          ^^^^^^^^^^^^^^^^^^^^^^^^^^^^^
  File "/home/airflow/.local/lib/python3.12/site-packages/airflow/cli/cli_config.py", line 49, in command
    return func(*args, **kwargs)
           ^^^^^^^^^^^^^^^^^^^^^
  File "/home/airflow/.local/lib/python3.12/site-packages/airflow/utils/cli.py", line 115, in wrapper
    return f(*args, **kwargs)
           ^^^^^^^^^^^^^^^^^^
  File "/home/airflow/.local/lib/python3.12/site-packages/airflow/cli/commands/task_command.py", line 483, in task_run
    task_return_code = _run_task_by_selected_method(args, _dag, ti)
                       ^^^^^^^^^^^^^^^^^^^^^^^^^^^^^^^^^^^^^^^^^^^^
  File "/home/airflow/.local/lib/python3.12/site-packages/airflow/cli/commands/task_command.py", line 256, in _run_task_by_selected_method
    return _run_raw_task(args, ti)
           ^^^^^^^^^^^^^^^^^^^^^^^
  File "/home/airflow/.local/lib/python3.12/site-packages/airflow/cli/commands/task_command.py", line 341, in _run_raw_task
    return ti._run_raw_task(
           ^^^^^^^^^^^^^^^^^
  File "/home/airflow/.local/lib/python3.12/site-packages/airflow/utils/session.py", line 97, in wrapper
    return func(*args, session=session, **kwargs)
           ^^^^^^^^^^^^^^^^^^^^^^^^^^^^^^^^^^^^^^
  File "/home/airflow/.local/lib/python3.12/site-packages/airflow/models/taskinstance.py", line 3004, in _run_raw_task
    return _run_raw_task(
           ^^^^^^^^^^^^^^
  File "/home/airflow/.local/lib/python3.12/site-packages/airflow/models/taskinstance.py", line 273, in _run_raw_task
    TaskInstance._execute_task_with_callbacks(
  File "/home/airflow/.local/lib/python3.12/site-packages/airflow/models/taskinstance.py", line 3158, in _execute_task_with_callbacks
    result = self._execute_task(context, task_orig)
             ^^^^^^^^^^^^^^^^^^^^^^^^^^^^^^^^^^^^^^
  File "/home/airflow/.local/lib/python3.12/site-packages/airflow/models/taskinstance.py", line 3182, in _execute_task
    return _execute_task(self, context, task_orig)
           ^^^^^^^^^^^^^^^^^^^^^^^^^^^^^^^^^^^^^^^
  File "/home/airflow/.local/lib/python3.12/site-packages/airflow/models/taskinstance.py", line 767, in _execute_task
    result = _execute_callable(context=context, **execute_callable_kwargs)
             ^^^^^^^^^^^^^^^^^^^^^^^^^^^^^^^^^^^^^^^^^^^^^^^^^^^^^^^^^^^^^
  File "/home/airflow/.local/lib/python3.12/site-packages/airflow/models/taskinstance.py", line 733, in _execute_callable
    return ExecutionCallableRunner(
           ^^^^^^^^^^^^^^^^^^^^^^^^
  File "/home/airflow/.local/lib/python3.12/site-packages/airflow/utils/operator_helpers.py", line 252, in run
    return self.func(*args, **kwargs)
           ^^^^^^^^^^^^^^^^^^^^^^^^^^
  File "/home/airflow/.local/lib/python3.12/site-packages/airflow/models/baseoperator.py", line 406, in wrapper
    return func(self, *args, **kwargs)
           ^^^^^^^^^^^^^^^^^^^^^^^^^^^
  File "/home/airflow/.local/lib/python3.12/site-packages/airflow/operators/python.py", line 238, in execute
    return_value = self.execute_callable()
                   ^^^^^^^^^^^^^^^^^^^^^^^
  File "/home/airflow/.local/lib/python3.12/site-packages/airflow/operators/python.py", line 256, in execute_callable
    return runner.run(*self.op_args, **self.op_kwargs)
           ^^^^^^^^^^^^^^^^^^^^^^^^^^^^^^^^^^^^^^^^^^^
  File "/home/airflow/.local/lib/python3.12/site-packages/airflow/utils/operator_helpers.py", line 252, in run
    return self.func(*args, **kwargs)
           ^^^^^^^^^^^^^^^^^^^^^^^^^^
  File "/opt/airflow/dags/tab_soccer_statics.py", line 83, in fact_matches_statistics
    pf.run()
  File "/opt/airflow/dags/src/soccer_statics/fact_matches_statics.py", line 37, in run
    data["fact_matches"] = self.__extract(
                           ^^^^^^^^^^^^^^^
  File "/opt/airflow/dags/src/soccer_statics/fact_matches_statics.py", line 188, in __extract
    data = pd.read_sql(query, conn_name.connection, params=params)
           ^^^^^^^^^^^^^^^^^^^^^^^^^^^^^^^^^^^^^^^^^^^^^^^^^^^^^^^
  File "/home/airflow/.local/lib/python3.12/site-packages/pandas/io/sql.py", line 682, in read_sql
    return pandas_sql.read_query(
           ^^^^^^^^^^^^^^^^^^^^^^
  File "/home/airflow/.local/lib/python3.12/site-packages/pandas/io/sql.py", line 1776, in read_query
    result = self.execute(sql, params)
             ^^^^^^^^^^^^^^^^^^^^^^^^^
  File "/home/airflow/.local/lib/python3.12/site-packages/pandas/io/sql.py", line 1599, in execute
    return self.con.exec_driver_sql(sql, *args)
           ^^^^^^^^^^^^^^^^^^^^^^^^^^^^^^^^^^^^
  File "/home/airflow/.local/lib/python3.12/site-packages/sqlalchemy/engine/base.py", line 1770, in exec_driver_sql
    return self._exec_driver_sql(
           ^^^^^^^^^^^^^^^^^^^^^^
  File "/home/airflow/.local/lib/python3.12/site-packages/sqlalchemy/engine/base.py", line 1674, in _exec_driver_sql
    ret = self._execute_context(
          ^^^^^^^^^^^^^^^^^^^^^^
  File "/home/airflow/.local/lib/python3.12/site-packages/sqlalchemy/engine/base.py", line 1953, in _execute_context
    self._handle_dbapi_exception(
  File "/home/airflow/.local/lib/python3.12/site-packages/sqlalchemy/engine/base.py", line 2134, in _handle_dbapi_exception
    util.raise_(
  File "/home/airflow/.local/lib/python3.12/site-packages/sqlalchemy/util/compat.py", line 211, in raise_
    raise exception
  File "/home/airflow/.local/lib/python3.12/site-packages/sqlalchemy/engine/base.py", line 1910, in _execute_context
    self.dialect.do_execute(
  File "/home/airflow/.local/lib/python3.12/site-packages/sqlalchemy/engine/default.py", line 736, in do_execute
    cursor.execute(statement, parameters)
sqlalchemy.exc.ProgrammingError: (psycopg2.errors.InvalidColumnReference) ORDER BY position 30 is not in select list
LINE 6: ORDER BY 30 DESC
                 ^

[SQL: 
SELECT id_match,date_match,fm."uuid"
FROM soccer.fact_matches fm 
LEFT JOIN soccer.fact_matches_statistics fms ON fm."uuid" = fms.uuid_match 
WHERE fms."uuid" IS NULL
ORDER BY 30 DESC
LIMIT 1
]
(Background on this error at: https://sqlalche.me/e/14/f405)
[2024-09-30T14:32:12.749+0000] {local_task_job_runner.py:266} INFO - Task exited with return code 1
[2024-09-30T14:32:12.761+0000] {taskinstance.py:3900} INFO - 0 downstream tasks scheduled from follow-on schedule check
[2024-09-30T14:32:12.762+0000] {local_task_job_runner.py:245} INFO - ::endgroup::
